Workbook

Sheet Variables
A1: Department: | B1: Interested | C1: Cleared
A2: Production Specialist 1 - Mechanical Assembly - A&C Shift
A3: Production Specialist 1 - Mechanical Assembly - B&D shift
A21: Total

Sheet Dashboard For Flex
A1: Applications | C1: Phone Screens | E1: Interviews | G1: Resume Subs
A2: Goal | B2: Attn | C2: Goal | D2: Attn | E2: Interviews Scheduled for today | F2: Interviews Scheduled for tomorrow | G2: Goal | H2: Attn | I2: Offers accepted | J2: Total in Pipeline | K2: Production Specialist 1 - Mechanical Assembly - A&C Shift | L2: Production Specialist 1 - Mechanical Assembly - A&C Shift Background cleared | M2: Production Specialist 1 - Mechanical Assembly - B&D shift | N2: Production Specialist 1 - Mechanical Assembly - B&D shift Background cleared | O2: Production Specialist 1 - Materials - A&C shift | P2: Production Specialist 1 - Materials - A&C shift Background cleared | Q2: Production Specialist 1 - Materials - B&D shift | R2: Production Specialist 1 - Materials - B&D shiftBackground cleared | S2: Production Specialist 1 - Rack Level Assembly - A&C shift | T2: Production Specialist 1 - Rack Level Assembly - A&C shift Background cleared | U2: Production Specialist 1 - Rack Level Assembly - B&D shift | V2: Production Specialist 1 - Rack Level Assembly - B&D shift Background cleared | W2: IT Support Technician - 1st Shift | X2: IT Support Technician - 1st Shift - Background cleared | Y2: Delivery Business Systems Analyst - 1st Shift | Z2: Delivery Business Systems Analyst - 1st Shift - Background cleared | AA2: Production Specialist 1 -Quality - B&D shift | AB2: Production Specialist 1 - Quality - B&D shift - Background cleared | AC2: Production Specialist 1 -Test Opertor - A&Cshift | AD2: Production Specialist 1 - Test Opertor - A&C shift - Background cleared | AE2: Production Specialist 1 - Mechanical Assy Debug - A&C shift | AF2: Production Specialist 1 - Mechanical Assy Debug - A&C shift - Background cleared | AG2: Debug Tech 4 - B&D shift | AH2: Debug Tech 4 - B&D shift - Background cleared | AI2: HR Generalist - 1st Shift | AJ2: Recruiter 1st Shift | AK2: Production Specialist 1 -Test Opertor - 1st shift | AL2: Production Specialist 1 - Test Opertor - 1st shift - Background cleared | AM2: Production Specialist 1 - Mechanical Assy Debug - 1st shift | AN2: Production Specialist 1 - Mechanical Assy Debug - 1st shift - Background cleared | AO2: Debug Tech 4 - 2nd shift | AP2: Debug Tech 4 - 2nd shift - Background cleared | AQ2: HR Generalist - 1st Shift | AR2: Recruiter 1st Shift

Sheet Dashboard
A1: Department: | B1: Interested | C1: Cleared
A2: Production Specialist 1 - Mechanical Assembly - 1st shift | B2: =COUNTIFS(PrepList!E:E,Dashboard!A2,PrepList'!M:M,"No") | C2: =COUNTIFS(PrepList!#REF!,Dashboard!A2,PrepList!#REF!,"Yes") -> #REF!
A3: Production Specialist 1 - Mechanical Assembly - 2nd shift | B3: =COUNTIFS(PrepList!H:H,Dashboard!A3,PrepList!#REF!,"No") -> #REF! | C3: =COUNTIFS(PrepList!#REF!,Dashboard!A3,PrepList!#REF!,"Yes") -> #REF!
A4: Production Specialist 1 - Materials - 1st shift | B4: =COUNTIFS(PrepList!H:H,Dashboard!A4,PrepList!#REF!,"No") -> #REF! | C4: =COUNTIFS(PrepList!#REF!,Dashboard!A4,PrepList!#REF!,"Yes") -> #REF!
A5: Production Specialist 1 - Materials - 2nd shift | B5: =COUNTIFS(PrepList!H:H,Dashboard!A5,PrepList!#REF!,"No") -> #REF! | C5: =COUNTIFS(PrepList!#REF!,Dashboard!A5,PrepList!#REF!,"Yes") -> #REF!
A6: Production Specialist 1 - Materials - 3rd shift | B6: =COUNTIFS(PrepList!H:H,Dashboard!A6,PrepList!#REF!,"No") -> #REF! | C6: =COUNTIFS(PrepList!#REF!,Dashboard!A6,PrepList!#REF!,"Yes") -> #REF!
A7: Production Specialist 1 - Mechanical Assembly - 3rd shift | B7: =COUNTIFS(PrepList!H:H,Dashboard!A7,PrepList!#REF!,"No") -> #REF! | C7: =COUNTIFS(PrepList!#REF!,Dashboard!A7,PrepList!#REF!,"Yes") -> #REF!
A8: Production Specialist 1 - Rack Level Assembly - 3rd shift | B8: =COUNTIFS(PrepList!H:H,Dashboard!A8,PrepList!#REF!,"No") -> #REF! | C8: =COUNTIFS(PrepList!#REF!,Dashboard!A8,PrepList!#REF!,"Yes") -> #REF!
A9: Production Specialist 1 - Packout - 3rd shift | B9: =COUNTIFS(PrepList!H:H,Dashboard!A9,PrepList!#REF!,"No") -> #REF! | C9: =COUNTIFS(PrepList!#REF!,Dashboard!A9,PrepList!#REF!,"Yes") -> #REF!
A10: Production Specialist 1 - Rack Level Assembly - 3rd shift | B10: =COUNTIFS(PrepList!H:H,Dashboard!A10,PrepList!#REF!,"No") -> #REF! | C10: =COUNTIFS(PrepList!#REF!,Dashboard!A10,PrepList!#REF!,"Yes") -> #REF!
A11: Production Specialist 1 - Rack Level Assembly -1st shift | B11: =COUNTIFS(PrepList!H:H,Dashboard!A11,PrepList!#REF!,"No") -> #REF! | C11: =COUNTIFS(PrepList!#REF!,Dashboard!A11,PrepList!#REF!,"Yes") -> #REF!
A12: Production Specialist 1 - Rack Level Assembly -2nd shift | B12: =COUNTIFS(PrepList!H:H,Dashboard!A12,PrepList!#REF!,"No") -> #REF! | C12: =COUNTIFS(PrepList!#REF!,Dashboard!A12,PrepList!#REF!,"Yes") -> #REF!
A13: IT Support Technician - 1st Shift | B13: =COUNTIFS(PrepList!H:H,Dashboard!A13,PrepList!#REF!,"No") -> #REF! | C13: =COUNTIFS(PrepList!#REF!,Dashboard!A13,PrepList!#REF!,"Yes") -> #REF!
A14: Delivery Business Systems Analyst - 1st Shift | B14: =COUNTIFS(PrepList!H:H,Dashboard!A14,PrepList!#REF!,"No") -> #REF! | C14: =COUNTIFS(PrepList!#REF!,Dashboard!A14,PrepList!#REF!,"Yes") -> #REF!
... A20: Recruiter 1st Shift | B20: =COUNTIFS(PrepList!H:H,Dashboard!A20,PrepList!#REF!,"No") -> #REF! | C20: =COUNTIFS(PrepList!#REF!,Dashboard!A20,PrepList!#REF!,"Yes") -> #REF!
A21: Total | B21: =SUM(B2:B20) -> #REF! | C21: =SUM(C2:C20) -> #REF!

Sheet Office Goals
A1: 2.24 - 2.28 | D1: as of 2.26
A2: Office | B2: Goal | C2: Actual
A3: NSL | B3: 10 | C3: 16
A4: WVC | B4: 20 | C4: 45
A5: WJ | B5: 20 | C5: 23
A6: Total | B6: =SUM(B3:B5) -> 50 | C6: =SUM(C3:C5) -> 84
A8: 3.03 - 3.07
A9: Office | B9: Goal | C9: Actual
A10: NSL | B10: 10
A11: WVC | B11: 20
A12: WJ | B12: 20
A13: Total | B13: =SUM(B10:B12) -> 50 | C13: =SUM(C10:C12) -> 0

Sheet MGR&Shifts
A1: Work Location | B1: Shift_Time | C1: Manager
A2: SLC-WH-RECIEVING & SHIPPING | B2: 0700a-0400p M-F some Saturday's | C2: Adam Coghlan (1034757)
A3: SLC-RACK ASSY- SUPERVISOR ASSY | B3: 8:30am to 5:00pm | C3: Alex Martinez
A4: SLC-RACK ASSY-IQA INSPECTION | B4: Salt Lake City- C 1st Shift 0630a-0300p Mon-Fri | C4: Alondra Landin (1152847)
A5: SLC-MECH ASSY- SUPERVISOR ASSY | B5: Salt Lake City - 12 - 0300p-1130p M-F | C5: Avigail Zamora
A6: SLC-MECH ASSY-ASSEMBLY | B6: 0800a-0500p M 1000a-0700p T-F | C6: Barbara Garcia (1137177)
A7: SLC-MECH ASSY-REWORK | B7: Salt Lake City- F 2nd Shift 0200p-1230a Mon-Th (15% Diff) | C7: Britton Hanna (1154396)
A8: SLC-RACK ASSY- SHIPPING | B8: Salt Lake City- Wknd Shift 0230p-0230a F-Sun (15% Diff) | C8: Castalia Marino
A9: SLC-WH-LEAD | B9: 0230p-1100p M-F some Saturday's | C9: Cristian Vega (1135987)
A10: SLC-MECH ASSY- WATER SPIDER | B10: Salt Lake City- D 1st Shift 0700a-0330p Mon-Fri | C10: Dallas Driggers (1156397)
A11: SLC-MECH ASSY-KITTING | B11: 0400p-0100a M-F some Saturday's | C11: Danilo Vieira De Souza Alves (60729)
A12: SLC-MECH ASSY-DETRASH | B12: 0330p-1200a M-F some Saturday's | C12: David Hiestand (1138434)
... A41: SLC-RACK ASSY-WATERSPIDER | B41: Salt Lake City - L - 10:00 PM - 6:30 AM (Sun-Thurs) | C41: Zee Fruechting (1167899)

Sheet Completed Orientation
A1: Employee Name | B1: Phone # | C1: Preferred Schedule | D1: Shift Requirement | E1: Position
A2: Ivonne Galban | B2: 801-500-3133 | C2: A/C (Day) | E2: =ROW() - ROW(Table52[[#Headers],[Position]]) -> 1
A3: Yulimar M Nazarin | B3: 313-523-3391 | C3: A/C (Day) | E3: =ROW() - ROW(Table52[[#Headers],[Position]]) -> 2
A4: Sindy Viviana Guillen Taborda | B4: 385-343-2625 | C4: A/C (Day) | E4: =ROW() - ROW(Table52[[#Headers],[Position]]) -> 3
A5: Abel Elias Huaman Huachopoma | B5: 385-421-1590 | C5: A/C (Day) | E5: =ROW() - ROW(Table52[[#Headers],[Position]]) -> 4
A6: David C Huaman Julian | B6: 801-946-9851 | C6: A/C (Day) | E6: =ROW() - ROW(Table52[[#Headers],[Position]]) -> 5
A7: Stivaliz Chirino | B7: 385-267-0910 | C7: A/C (Day) | E7: =ROW() - ROW(Table52[[#Headers],[Position]]) -> 6
A8: Cruzmar Danielo Azuaje Briceno | B8: 801-895-1504 | C8: A/C (Day) | E8: =ROW() - ROW(Table52[[#Headers],[Position]]) -> 7
A9: Gloria N Navarro | B9: 385-302-2818 | C9: A/C (Day) | E9: =ROW() - ROW(Table52[[#Headers],[Position]]) -> 8
A10: Maria Duram | B10: 689-204-4662 | C10: A/C (Day) | E10: =ROW() - ROW(Table52[[#Headers],[Position]]) -> 9
A11: Ginelda Palmar | B11: 385-343-9591 | C11: A/C (Day) | E11: =ROW() - ROW(Table52[[#Headers],[Position]]) -> 10
A12: Juan Acero Diaz | B12: 813-521-3185 | C12: A/C (Day) | E12: =ROW() - ROW(Table52[[#Headers],[Position]]) -> 11
A13: Maria Mercedes Ibarra | B13: 801-584-9577 | C13: A/C (Day) | E13: =ROW() - ROW(Table52[[#Headers],[Position]]) -> 12
... A15: Juan Nova | B15: 385-576-3439 | C15: A/C (Day) | E15: =ROW() - ROW(Table52[[#Headers],[Position]]) -> 14
A16: Jesse Gonzalez | C16: A/C (Day) | E16: =ROW() - ROW(Table52[[#Headers],[Position]]) -> 15
A17: Christian Crush | C17: A/C (Day) | E17: =ROW() - ROW(Table52[[#Headers],[Position]]) -> 16
A18: Gabriela Molina | B18: 385-267-9020 | C18: A/C (Day) | D18: Luzmila Ballesteros | E18: =ROW() - ROW(Table52[[#Headers],[Position]]) -> 17
A19: Jesse Gonzalez | B19: 801-809-7918 | C19: A/C (Day) | E19: =ROW() - ROW(Table52[[#Headers],[Position]]) -> 18
A20: Christian Crush | B20: 409-730-6234 | C20: A/C (Day) | E20: =ROW() - ROW(Table52[[#Headers],[Position]]) -> 19
A21: Gisell Carmona | B21: 385-441-2390 | C21: A/C (Day) | D21: Catherine Rodriguez | E21: =ROW() - ROW(Table52[[#Headers],[Position]]) -> 20
A22: Catherine Rodriguez | B22: (801) 330-2018 | C22: A/C (Day) | D22: Gisell Carmona | E22: =ROW() - ROW(Table52[[#Headers],[Position]]) -> 21
A23: Mariely Gonzalez | B23: 801-674-5096 | C23: A/C (Day) | E23: =ROW() - ROW(Table52[[#Headers],[Position]]) -> 22
A24: Craig Allen Foster | B24: 406-381-3640 | C24: A/C (Day) | E24: =ROW() - ROW(Table52[[#Headers],[Position]]) -> 23
A25: Lizbeth Zavala | B25: 801-708-9014 | C25: A/C (Day) | E25: =ROW() - ROW(Table52[[#Headers],[Position]]) -> 24
A26: Syreefa Yazzie | B26: 385-887-1774 | C26: A/C (Day) | D26: Timothy Alires | E26: =ROW() - ROW(Table52[[#Headers],[Position]]) -> 25
A27: Jerja Chatterton | B27: 435-755-0810 | C27: A/C (Day) | E27: =ROW() - ROW(Table52[[#Headers],[Position]]) -> 26
A28: Jennifer Lee | B28: 385-258-9659 | C28: A/C (Day) | E28: =ROW() - ROW(Table52[[#Headers],[Position]]) -> 27
A29: Sabha Abrena | B29: 385-299-1604 | C29: A/C (Day) | E29: =ROW() - ROW(Table52[[#Headers],[Position]]) -> 28
A30: Taylor W Lawer | B30: 707-378-3290 | C30: A/C (Day) | E30: =ROW() - ROW(Table52[[#Headers],[Position]]) -> 29
A31: Sophie Wesseh | B31: 385-520-3599 | C31: A/C (Day) | E31: =ROW() - ROW(Table52[[#Headers],[Position]]) -> 30
A32: Norris John | B32: 949-393-8177 | C32: A/C (Day) | D32: 385-401-3966 | E32: =ROW() - ROW(Table52[[#Headers],[Position]]) -> 31
A33: Lotomaci BJ Uluset? | B33: 385-566-7922 | C33: A/C (Day) | D33: Robert Tiana | E33: =ROW() - ROW(Table52[[#Headers],[Position]]) -> 32
A34: Rober Tiana | B34: 385-566-7922 | C34: A/C (Day) | D34: BJ | E34: =ROW() - ROW(Table52[[#Headers],[Position]]) -> 33
A35: Arely Cardenas | B35: 801-824-7474 | C35: A/C (Day) | D35: C | E35: =ROW() - ROW(Table52[[#Headers],[Position]]) -> 34
A36: Ulises Anzaldo | B36: 385-770-9129 | C36: A/C (Day) | E36: =ROW() - ROW(Table52[[#Headers],[Position]]) -> 35
A37: Hawa Enow | B37: 801-618-5641 | C37: A/C (Day) | E37: =ROW() - ROW(Table52[[#Headers],[Position]]) -> 36
A38: Jhony Mauricio | B38: 385-900-6827 | C38: A/C (Day) | E38: =ROW() - ROW(Table52[[#Headers],[Position]]) -> 37
A39: Mary Cruz Parra | B39: 385-461-2852 | C39: A/C (Day) | E39: =ROW() - ROW(Table52[[#Headers],[Position]]) -> 38
A40: Yendri Merentes | B40: 801-430-4477 | C40: A/C (Day) | E40: =ROW() - ROW(Table52[[#Headers],[Position]]) -> 39
A41: Angel Enrique Chacin Romero | B41: 801-414-0925 | C41: A/C (Day) | E41: =ROW() - ROW(Table52[[#Headers],[Position]]) -> 40
...

Sheet Ready to Start
A1: Mini Completed Date | B1: Language | C1: Employee Name | D1: Bold ID | E1: Phone | F1: Shift | G1: Position | H1: A.M. | I1: BG | J1: DT | K1: EV | L1: FLEX Doc Sent | M1: Ready to Start | N1: Notes
B2: =IF(PrepList!#REF!="","",PrepList!#REF!) -> #REF! | C2: =_xlfn.XLOOKUP(D2,PrepList!F:F,PrepList!E:E) -> #REF! | D2: =IF(PrepList!#REF!="","",PrepList!#REF!) -> #REF! | E2: =IF(PrepList!#REF!="","",PrepList!#REF!) -> #REF! | F2: =IF(PrepList!#REF!="","",PrepList!#REF!) -> #REF! | G2: =IF(PrepList!#REF!="","",PrepList!#REF!) -> #REF! | H2: =IF(PrepList!#REF!="","",PrepList!#REF!) -> #REF! | I2: =IF(PrepList!#REF!="","",PrepList!#REF!) -> #REF! | J2: =IF(PrepList!#REF!="","",PrepList!#REF!) -> #REF! | L2: =IF(PrepList!#REF!="","",PrepList!#REF!) -> #REF! | N2: =IF(PrepList!#REF!="","",PrepList!#REF!) -> #REF!
B3: =IF(PrepList!#REF!="","",PrepList!#REF!) -> #REF! | C3: =_xlfn.XLOOKUP(D3,PrepList!F:F,PrepList!E:E) -> #REF! | D3: =IF(PrepList!#REF!="","",PrepList!#REF!) -> #REF! | E3: =IF(PrepList!#REF!="","",PrepList!#REF!) -> #REF! | F3: =IF(PrepList!#REF!="","",PrepList!#REF!) -> #REF! | G3: =IF(PrepList!#REF!="","",PrepList!#REF!) -> #REF! | H3: =IF(PrepList!#REF!="","",PrepList!#REF!) -> #REF! | I3: =IF(PrepList!#REF!="","",PrepList!#REF!) -> #REF! | J3: =IF(PrepList!#REF!="","",PrepList!#REF!) -> #REF! | L3: =IF(PrepList!#REF!="","",PrepList!#REF!) -> #REF! | N3: =IF(PrepList!#REF!="","",PrepList!#REF!) -> #REF!
B4: =IF(PrepList!#REF!="","",PrepList!#REF!) -> #REF! | C4: =_xlfn.XLOOKUP(D4,PrepList!F:F,PrepList!E:E) -> #REF! | D4: =IF(PrepList!#REF!="","",PrepList!#REF!) -> #REF! | E4: =IF(PrepList!#REF!="","",PrepList!#REF!) -> #REF! | F4: =IF(PrepList!#REF!="","",PrepList!#REF!) -> #REF! | G4: =IF(PrepList!#REF!="","",PrepList!#REF!) -> #REF! | H4: =IF(PrepList!#REF!="","",PrepList!#REF!) -> #REF! | I4: =IF(PrepList!#REF!="","",PrepList!#REF!) -> #REF! | J4: =IF(PrepList!#REF!="","",PrepList!#REF!) -> #REF! | L4: =IF(PrepList!#REF!="","",PrepList!#REF!) -> #REF! | N4: =IF(PrepList!#REF!="","",PrepList!#REF!) -> #REF!
B5: =IF(PrepList!#REF!="","",PrepList!#REF!) -> #REF! | C5: =_xlfn.XLOOKUP(D5,PrepList!F:F,PrepList!E:E) -> #REF! | D5: =IF(PrepList!#REF!="","",PrepList!#REF!) -> #REF! | E5: =IF(PrepList!#REF!="","",PrepList!#REF!) -> #REF! | F5: =IF(PrepList!#REF!="","",PrepList!#REF!) -> #REF! | G5: =IF(PrepList!#REF!="","",PrepList!#REF!) -> #REF! | H5: =IF(PrepList!#REF!="","",PrepList!#REF!) -> #REF! | I5: =IF(PrepList!#REF!="","",PrepList!#REF!) -> #REF! | J5: =IF(PrepList!#REF!="","",PrepList!#REF!) -> #REF! | L5: =IF(PrepList!#REF!="","",PrepList!#REF!) -> #REF! | N5: =IF(PrepList!#REF!="","",PrepList!#REF!) -> #REF!
B6: =IF(PrepList!#REF!="","",PrepList!#REF!) -> #REF! | C6: =_xlfn.XLOOKUP(D6,PrepList!F:F,PrepList!E:E) -> #REF! | D6: =IF(PrepList!#REF!="","",PrepList!#REF!) -> #REF! | E6: =IF(PrepList!#REF!="","",PrepList!#REF!) -> #REF! | F6: =IF(PrepList!#REF!="","",PrepList!#REF!) -> #REF! | G6: =IF(PrepList!#REF!="","",PrepList!#REF!) -> #REF! | H6: =IF(PrepList!#REF!="","",PrepList!#REF!) -> #REF! | I6: =IF(PrepList!#REF!="","",PrepList!#REF!) -> #REF! | J6: =IF(PrepList!#REF!="","",PrepList!#REF!) -> #REF! | L6: =IF(PrepList!#REF!="","",PrepList!#REF!) -> #REF! | N6: =IF(PrepList!#REF!="","",PrepList!#REF!) -> #REF!
B7: =IF(PrepList!#REF!="","",PrepList!#REF!) -> #REF! | C7: =_xlfn.XLOOKUP(D7,PrepList!F:F,PrepList!E:E) -> #REF! | D7: =IF(PrepList!#REF!="","",PrepList!#REF!) -> #REF! | E7: =IF(PrepList!#REF!="","",PrepList!#REF!) -> #REF! | F7: =IF(PrepList!#REF!="","",PrepList!#REF!) -> #REF! | G7: =IF(PrepList!#REF!="","",PrepList!#REF!) -> #REF! | H7: =IF(PrepList!#REF!="","",PrepList!#REF!) -> #REF! | I7: =IF(PrepList!#REF!="","",PrepList!#REF!) -> #REF! | J7: =IF(PrepList!#REF!="","",PrepList!#REF!) -> #REF! | L7: =IF(PrepList!#REF!="","",PrepList!#REF!) -> #REF! | N7: =IF(PrepList!#REF!="","",PrepList!#REF!) -> #REF!
B8: =IF(PrepList!#REF!="","",PrepList!#REF!) -> #REF! | C8: =_xlfn.XLOOKUP(D8,PrepList!F:F,PrepList!E:E) -> #REF! | D8: =IF(PrepList!#REF!="","",PrepList!#REF!) -> #REF! | E8: =IF(PrepList!#REF!="","",PrepList!#REF!) -> #REF! | F8: =IF(PrepList!#REF!="","",PrepList!#REF!) -> #REF! | G8: =IF(PrepList!#REF!="","",PrepList!#REF!) -> #REF! | H8: =IF(PrepList!#REF!="","",PrepList!#REF!) -> #REF! | I8: =IF(PrepList!#REF!="","",PrepList!#REF!) -> #REF! | J8: =IF(PrepList!#REF!="","",PrepList!#REF!) -> #REF! | L8: =IF(PrepList!#REF!="","",PrepList!#REF!) -> #REF! | N8: =IF(PrepList!#REF!="","",PrepList!#REF!) -> #REF!
B9: =IF(PrepList!#REF!="","",PrepList!#REF!) -> #REF! | C9: =_xlfn.XLOOKUP(D9,PrepList!F:F,PrepList!E:E) -> #REF! | D9: =IF(PrepList!#REF!="","",PrepList!#REF!) -> #REF! | E9: =IF(PrepList!#REF!="","",PrepList!#REF!) -> #REF! | F9: =IF(PrepList!#REF!="","",PrepList!#REF!) -> #REF! | G9: =IF(PrepList!#REF!="","",PrepList!#REF!) -> #REF! | H9: =IF(PrepList!#REF!="","",PrepList!#REF!) -> #REF! | I9: =IF(PrepList!#REF!="","",PrepList!#REF!) -> #REF! | J9: =IF(PrepList!#REF!="","",PrepList!#REF!) -> #REF! | L9: =IF(PrepList!#REF!="","",PrepList!#REF!) -> #REF! | N9: =IF(PrepList!#REF!="","",PrepList!#REF!) -> #REF!
B10: =IF(PrepList!#REF!="","",PrepList!#REF!) -> #REF! | C10: =_xlfn.XLOOKUP(D10,PrepList!F:F,PrepList!E:E) -> #REF! | D10: =IF(PrepList!#REF!="","",PrepList!#REF!) -> #REF! | E10: =IF(PrepList!#REF!="","",PrepList!#REF!) -> #REF! | F10: =IF(PrepList!#REF!="","",PrepList!#REF!) -> #REF! | G10: =IF(PrepList!#REF!="","",PrepList!#REF!) -> #REF! | H10: =IF(PrepList!#REF!="","",PrepList!#REF!) -> #REF! | I10: =IF(PrepList!#REF!="","",PrepList!#REF!) -> #REF! | J10: =IF(PrepList!#REF!="","",PrepList!#REF!) -> #REF! | L10: =IF(PrepList!#REF!="","",PrepList!#REF!) -> #REF! | N10: =IF(PrepList!#REF!="","",PrepList!#REF!) -> #REF!
B11: =IF(PrepList!#REF!="","",PrepList!#REF!) -> #REF! | C11: =_xlfn.XLOOKUP(D11,PrepList!F:F,PrepList!E:E) -> #REF! | D11: =IF(PrepList!#REF!="","",PrepList!#REF!) -> #REF! | E11: =IF(PrepList!#REF!="","",PrepList!#REF!) -> #REF! | F11: =IF(PrepList!#REF!="","",PrepList!#REF!) -> #REF! | G11: =IF(PrepList!#REF!="","",PrepList!#REF!) -> #REF! | H11: =IF(PrepList!#REF!="","",PrepList!#REF!) -> #REF! | I11: =IF(PrepList!#REF!="","",PrepList!#REF!) -> #REF! | J11: =IF(PrepList!#REF!="","",PrepList!#REF!) -> #REF! | L11: =IF(PrepList!#REF!="","",PrepList!#REF!) -> #REF! | N11: =IF(PrepList!#REF!="","",PrepList!#REF!) -> #REF!
B12: =IF(PrepList!#REF!="","",PrepList!#REF!) -> #REF! | C12: =_xlfn.XLOOKUP(D12,PrepList!F:F,PrepList!E:E) -> #REF! | D12: =IF(PrepList!#REF!="","",PrepList!#REF!) -> #REF! | E12: =IF(PrepList!#REF!="","",PrepList!#REF!) -> #REF! | F12: =IF(PrepList!#REF!="","",PrepList!#REF!) -> #REF! | G12: =IF(PrepList!#REF!="","",PrepList!#REF!) -> #REF! | H12: =IF(PrepList!#REF!="","",PrepList!#REF!) -> #REF! | I12: =IF(PrepList!#REF!="","",PrepList!#REF!) -> #REF! | J12: =IF(PrepList!#REF!="","",PrepList!#REF!) -> #REF! | L12: =IF(PrepList!#REF!="","",PrepList!#REF!) -> #REF! | N12: =IF(PrepList!#REF!="","",PrepList!#REF!) -> #REF!
B13: =IF(PrepList!#REF!="","",PrepList!#REF!) -> #REF! | C13: =_xlfn.XLOOKUP(D13,PrepList!F:F,PrepList!E:E) -> #REF! | D13: =IF(PrepList!#REF!="","",PrepList!#REF!) -> #REF! | E13: =IF(PrepList!#REF!="","",PrepList!#REF!) -> #REF! | F13: =IF(PrepList!#REF!="","",PrepList!#REF!) -> #REF! | G13: =IF(PrepList!#REF!="","",PrepList!#REF!) -> #REF! | H13: =IF(PrepList!#REF!="","",PrepList!#REF!) -> #REF! | I13: =IF(PrepList!#REF!="","",PrepList!#REF!) -> #REF! | J13: =IF(PrepList!#REF!="","",PrepList!#REF!) -> #REF! | L13: =IF(PrepList!#REF!="","",PrepList!#REF!) -> #REF! | N13: =IF(PrepList!#REF!="","",PrepList!#REF!) -> #REF!
... B170: =IF(PrepList!#REF!="","",PrepList!#REF!) -> #REF! | C170: =_xlfn.XLOOKUP(D170,PrepList!F:F,PrepList!E:E) -> #REF! | D170: =IF(PrepList!#REF!="","",PrepList!#REF!) -> #REF! | E170: =IF(PrepList!#REF!="","",PrepList!#REF!) -> #REF! | F170: =IF(PrepList!#REF!="","",PrepList!#REF!) -> #REF! | G170: =IF(PrepList!#REF!="","",PrepList!#REF!) -> #REF! | H170: =IF(PrepList!#REF!="","",PrepList!#REF!) -> #REF! | I170: =IF(PrepList!#REF!="","",PrepList!#REF!) -> #REF! | J170: =IF(PrepList!#REF!="","",PrepList!#REF!) -> #REF! | L170: =IF(PrepList!#REF!="","",PrepList!#REF!) -> #REF! | N170: =IF(PrepList!#REF!="","",PrepList!#REF!) -> #REF!
B171: =IF(PrepList!D2="","",PrepList!D2) -> Spanish | C171: =_xlfn.XLOOKUP(D171,PrepList!F:F,PrepList!E:E) -> Doraxci Gonzalez | D171: =IF(PrepList!F2="","",PrepList!F2) -> 177671254 | E171: =IF(PrepList!G2="","",PrepList!G2) -> 3856289600 | F171: =IF(PrepList!H2="","",PrepList!H2) -> Day Shift | G171: =IF(PrepList!I2="","",PrepList!I2) -> Mechanical Assembly | H171: =IF(PrepList!K2="","",PrepList!K2) -> FZ | I171: =IF(PrepList!L2="","",PrepList!L2) -> Pending | J171: =IF(PrepList!M2="","",PrepList!M2) | L171: =IF(PrepList!N2="","",PrepList!N2) -> Passed | N171: =IF(PrepList!P2="","",PrepList!P2) -> Confirmed on 8/26 she is still interested
B172: =IF(PrepList!D3="","",PrepList!D3) -> Spanish | C172: =_xlfn.XLOOKUP(D172,PrepList!F:F,PrepList!E:E) -> Maralis Mendoza | D172: =IF(PrepList!F3="","",PrepList!F3) -> 198173510 | E172: =IF(PrepList!G3="","",PrepList!G3) -> 3852164295 | F172: =IF(PrepList!H3="","",PrepList!H3) -> Day Shift | G172: =IF(PrepList!I3="","",PrepList!I3) -> Mechanical Assembly | H172: =IF(PrepList!K3="","",PrepList!K3) -> BL | I172: =IF(PrepList!L3="","",PrepList!L3) -> Passed | J172: =IF(PrepList!M3="","",PrepList!M3) -> Passed | L172: =IF(PrepList!N3="","",PrepList!N3) -> Passed | N172: =IF(PrepList!P3="","",PrepList!P3) -> Confirmed on 8/26 she is still interested
B173: =IF(PrepList!#REF!="","",PrepList!#REF!) -> #REF! | C173: =_xlfn.XLOOKUP(D173,PrepList!F:F,PrepList!E:E) -> #REF! | D173: =IF(PrepList!#REF!="","",PrepList!#REF!) -> #REF! | E173: =IF(PrepList!#REF!="","",PrepList!#REF!) -> #REF! | F173: =IF(PrepList!#REF!="","",PrepList!#REF!) -> #REF! | G173: =IF(PrepList!#REF!="","",PrepList!#REF!) -> #REF! | H173: =IF(PrepList!#REF!="","",PrepList!#REF!) -> #REF! | I173: =IF(PrepList!#REF!="","",PrepList!#REF!) -> #REF! | J173: =IF(PrepList!#REF!="","",PrepList!#REF!) -> #REF! | L173: =IF(PrepList!#REF!="","",PrepList!#REF!) -> #REF! | N173: =IF(PrepList!#REF!="","",PrepList!#REF!) -> #REF!
B174: =IF(PrepList!D4="","",PrepList!D4) -> Spanish | C174: =_xlfn.XLOOKUP(D174,PrepList!F:F,PrepList!E:E) -> Edna Dominguez | D174: =IF(PrepList!F4="","",PrepList!F4) -> 148926496 | E174: =IF(PrepList!G4="","",PrepList!G4) -> 8019185846 | F174: =IF(PrepList!H4="","",PrepList!H4) -> Night Shift | G174: =IF(PrepList!I4="","",PrepList!I4) -> Mechanical Assembly | H174: =IF(PrepList!K4="","",PrepList!K4) -> CE | I174: =IF(PrepList!L4="","",PrepList!L4) -> Passed | J174: =IF(PrepList!M4="","",PrepList!M4) -> Passed | L174: =IF(PrepList!N4="","",PrepList!N4) -> Passed | N174: =IF(PrepList!P4="","",PrepList!P4) -> She stated she wont be in Utah for a few months?
B175: =IF(PrepList!D5="","",PrepList!D5) -> Spanish | C175: =_xlfn.XLOOKUP(D175,PrepList!F:F,PrepList!E:E) -> Amayrany Hernandez | D175: =IF(PrepList!F5="","",PrepList!F5) -> 198303055 | E175: =IF(PrepList!G5="","",PrepList!G5) -> 3855410937 | F175: =IF(PrepList!H5="","",PrepList!H5) -> Night Shift | G175: =IF(PrepList!I5="","",PrepList!I5) -> Mechanical Assembly | H175: =IF(PrepList!K5="","",PrepList!K5) -> CE | I175: =IF(PrepList!L5="","",PrepList!L5) -> Passed | J175: =IF(PrepList!M5="","",PrepList!M5) -> Passed | L175: =IF(PrepList!N5="","",PrepList!N5) -> Passed | N175: =IF(PrepList!P5="","",PrepList!P5) -> Confirmed on 8/26 she is still interested
B176: =IF(PrepList!#REF!="","",PrepList!#REF!) -> #REF! | C176: =_xlfn.XLOOKUP(D176,PrepList!F:F,PrepList!E:E) -> #REF! | D176: =IF(PrepList!#REF!="","",PrepList!#REF!) -> #REF! | E176: =IF(PrepList!#REF!="","",PrepList!#REF!) -> #REF! | F176: =IF(PrepList!#REF!="","",PrepList!#REF!) -> #REF! | G176: =IF(PrepList!#REF!="","",PrepList!#REF!) -> #REF! | H176: =IF(PrepList!#REF!="","",PrepList!#REF!) -> #REF! | I176: =IF(PrepList!#REF!="","",PrepList!#REF!) -> #REF! | J176: =IF(PrepList!#REF!="","",PrepList!#REF!) -> #REF! | L176: =IF(PrepList!#REF!="","",PrepList!#REF!) -> #REF! | N176: =IF(PrepList!#REF!="","",PrepList!#REF!) -> #REF!
B177: =IF(PrepList!#REF!="","",PrepList!#REF!) -> #REF! | C177: =_xlfn.XLOOKUP(D177,PrepList!F:F,PrepList!E:E) -> #REF! | D177: =IF(PrepList!#REF!="","",PrepList!#REF!) -> #REF! | E177: =IF(PrepList!#REF!="","",PrepList!#REF!) -> #REF! | F177: =IF(PrepList!#REF!="","",PrepList!#REF!) -> #REF! | G177: =IF(PrepList!#REF!="","",PrepList!#REF!) -> #REF! | H177: =IF(PrepList!#REF!="","",PrepList!#REF!) -> #REF! | I177: =IF(PrepList!#REF!="","",PrepList!#REF!) -> #REF! | J177: =IF(PrepList!#REF!="","",PrepList!#REF!) -> #REF! | L177: =IF(PrepList!#REF!="","",PrepList!#REF!) -> #REF! | N177: =IF(PrepList!#REF!="","",PrepList!#REF!) -> #REF!
B178: =IF(PrepList!#REF!="","",PrepList!#REF!) -> #REF! | C178: =_xlfn.XLOOKUP(D178,PrepList!F:F,PrepList!E:E) -> #REF! | D178: =IF(PrepList!#REF!="","",PrepList!#REF!) -> #REF! | E178: =IF(PrepList!#REF!="","",PrepList!#REF!) -> #REF! | F178: =IF(PrepList!#REF!="","",PrepList!#REF!) -> #REF! | G178: =IF(PrepList!#REF!="","",PrepList!#REF!) -> #REF! | H178: =IF(PrepList!#REF!="","",PrepList!#REF!) -> #REF! | I178: =IF(PrepList!#REF!="","",PrepList!#REF!) -> #REF! | J178: =IF(PrepList!#REF!="","",PrepList!#REF!) -> #REF! | L178: =IF(PrepList!#REF!="","",PrepList!#REF!) -> #REF! | N178: =IF(PrepList!#REF!="","",PrepList!#REF!) -> #REF!
B179: =IF(PrepList!#REF!="","",PrepList!#REF!) -> #REF! | C179: =_xlfn.XLOOKUP(D179,PrepList!F:F,PrepList!E:E) -> #REF! | D179: =IF(PrepList!#REF!="","",PrepList!#REF!) -> #REF! | E179: =IF(PrepList!#REF!="","",PrepList!#REF!) -> #REF! | F179: =IF(PrepList!#REF!="","",PrepList!#REF!) -> #REF! | G179: =IF(PrepList!#REF!="","",PrepList!#REF!) -> #REF! | H179: =IF(PrepList!#REF!="","",PrepList!#REF!) -> #REF! | I179: =IF(PrepList!#REF!="","",PrepList!#REF!) -> #REF! | J179: =IF(PrepList!#REF!="","",PrepList!#REF!) -> #REF! | L179: =IF(PrepList!#REF!="","",PrepList!#REF!) -> #REF! | N179: =IF(PrepList!#REF!="","",PrepList!#REF!) -> #REF!
B180: =IF(PrepList!D6="","",PrepList!D6) -> Spanish | C180: =_xlfn.XLOOKUP(D180,PrepList!F:F,PrepList!E:E) -> Aracely Hernandez | D180: =IF(PrepList!F6="","",PrepList!F6) -> 198318924 | E180: =IF(PrepList!G6="","",PrepList!G6) -> 4357141187 | F180: =IF(PrepList!H6="","",PrepList!H6) -> Night Shift | G180: =IF(PrepList!I6="","",PrepList!I6) -> Mechanical Assembly | H180: =IF(PrepList!K6="","",PrepList!K6) -> CE | I180: =IF(PrepList!L6="","",PrepList!L6) -> Passed | J180: =IF(PrepList!M6="","",PrepList!M6) -> Passed | L180: =IF(PrepList!N6="","",PrepList!N6) -> Passed | N180: =IF(PrepList!P6="","",PrepList!P6)
B181: =IF(PrepList!D7="","",PrepList!D7) -> Spanish | C181: =_xlfn.XLOOKUP(D181,PrepList!F:F,PrepList!E:E) -> Snayder Pongo | D181: =IF(PrepList!F7="","",PrepList!F7) -> 198237668 | E181: =IF(PrepList!G7="","",PrepList!G7) -> 3854883070 | F181: =IF(PrepList!H7="","",PrepList!H7) -> Day Shift | G181: =IF(PrepList!I7="","",PrepList!I7) -> Mechanical Assembly | H181: =IF(PrepList!K7="","",PrepList!K7) -> NM | I181: =IF(PrepList!L7="","",PrepList!L7) -> Passed | J181: =IF(PrepList!M7="","",PrepList!M7) -> Passed | L181: =IF(PrepList!N7="","",PrepList!N7) -> Passed | N181: =IF(PrepList!P7="","",PrepList!P7)
B182: =IF(PrepList!D8="","",PrepList!D8) -> Spanish | C182: =_xlfn.XLOOKUP(D182,PrepList!F:F,PrepList!E:E) -> Yennifer Hernandez | D182: =IF(PrepList!F8="","",PrepList!F8) -> 186325204 | E182: =IF(PrepList!G8="","",PrepList!G8) -> 8015094766 | F182: =IF(PrepList!H8="","",PrepList!H8) -> Day Shift | G182: =IF(PrepList!I8="","",PrepList!I8) -> Mechanical Assembly | H182: =IF(PrepList!K8="","",PrepList!K8) -> BL | I182: =IF(PrepList!L8="","",PrepList!L8) -> Passed | J182: =IF(PrepList!M8="","",PrepList!M8) -> Passed | L182: =IF(PrepList!N8="","",PrepList!N8) -> Passed | N182: =IF(PrepList!P8="","",PrepList!P8)
B183: =IF(PrepList!#REF!="","",PrepList!#REF!) -> #REF! | C183: =_xlfn.XLOOKUP(D183,PrepList!F:F,PrepList!E:E) -> #REF! | D183: =IF(PrepList!#REF!="","",PrepList!#REF!) -> #REF! | E183: =IF(PrepList!#REF!="","",PrepList!#REF!) -> #REF! | F183: =IF(PrepList!#REF!="","",PrepList!#REF!) -> #REF! | G183: =IF(PrepList!#REF!="","",PrepList!#REF!) -> #REF! | H183: =IF(PrepList!#REF!="","",PrepList!#REF!) -> #REF! | I183: =IF(PrepList!#REF!="","",PrepList!#REF!) -> #REF! | J183: =IF(PrepList!#REF!="","",PrepList!#REF!) -> #REF! | L183: =IF(PrepList!#REF!="","",PrepList!#REF!) -> #REF! | N183: =IF(PrepList!#REF!="","",PrepList!#REF!) -> #REF!
B184: =IF(PrepList!#REF!="","",PrepList!#REF!) -> #REF! | C184: =_xlfn.XLOOKUP(D184,PrepList!F:F,PrepList!E:E) -> #REF! | D184: =IF(PrepList!#REF!="","",PrepList!#REF!) -> #REF! | E184: =IF(PrepList!#REF!="","",PrepList!#REF!) -> #REF! | F184: =IF(PrepList!#REF!="","",PrepList!#REF!) -> #REF! | G184: =IF(PrepList!#REF!="","",PrepList!#REF!) -> #REF! | H184: =IF(PrepList!#REF!="","",PrepList!#REF!) -> #REF! | I184: =IF(PrepList!#REF!="","",PrepList!#REF!) -> #REF! | J184: =IF(PrepList!#REF!="","",PrepList!#REF!) -> #REF! | L184: =IF(PrepList!#REF!="","",PrepList!#REF!) -> #REF! | N184: =IF(PrepList!#REF!="","",PrepList!#REF!) -> #REF!
B185: =IF(PrepList!#REF!="","",PrepList!#REF!) -> #REF! | C185: =_xlfn.XLOOKUP(D185,PrepList!F:F,PrepList!E:E) -> #REF! | D185: =IF(PrepList!#REF!="","",PrepList!#REF!) -> #REF! | E185: =IF(PrepList!#REF!="","",PrepList!#REF!) -> #REF! | F185: =IF(PrepList!#REF!="","",PrepList!#REF!) -> #REF! | G185: =IF(PrepList!#REF!="","",PrepList!#REF!) -> #REF! | H185: =IF(PrepList!K9="","",PrepList!K9) -> BL | I185: =IF(PrepList!L9="","",PrepList!L9) -> Passed | J185: =IF(PrepList!M9="","",PrepList!M9) -> Passed | L185: =IF(PrepList!#REF!="","",PrepList!#REF!) -> #REF! | N185: =IF(PrepList!#REF!="","",PrepList!#REF!) -> #REF!
B186: =IF(PrepList!D9="","",PrepList!D9) -> Spanish | C186: =_xlfn.XLOOKUP(D186,PrepList!F:F,PrepList!E:E) -> Norelkys Gallardo | D186: =IF(PrepList!F9="","",PrepList!F9) -> 185565315 | E186: =IF(PrepList!G9="","",PrepList!G9) -> 3855907316 | F186: =IF(PrepList!H9="","",PrepList!H9) -> Day Shift | G186: =IF(PrepList!I9="","",PrepList!I9) -> Mechanical Assembly | H186: =IF(PrepList!#REF!="","",PrepList!#REF!) -> #REF! | I186: =IF(PrepList!#REF!="","",PrepList!#REF!) -> #REF! | J186: =IF(PrepList!#REF!="","",PrepList!#REF!) -> #REF! | L186: =IF(PrepList!N9="","",PrepList!N9) -> Passed | N186: =IF(PrepList!P9="","",PrepList!P9)
B187: =IF(PrepList!#REF!="","",PrepList!#REF!) -> #REF! | C187: =_xlfn.XLOOKUP(D187,PrepList!F:F,PrepList!E:E) -> #REF! | D187: =IF(PrepList!#REF!="","",PrepList!#REF!) -> #REF! | E187: =IF(PrepList!#REF!="","",PrepList!#REF!) -> #REF! | F187: =IF(PrepList!#REF!="","",PrepList!#REF!) -> #REF! | G187: =IF(PrepList!#REF!="","",PrepList!#REF!) -> #REF! | H187: =IF(PrepList!#REF!="","",PrepList!#REF!) -> #REF! | I187: =IF(PrepList!#REF!="","",PrepList!#REF!) -> #REF! | J187: =IF(PrepList!#REF!="","",PrepList!#REF!) -> #REF! | L187: =IF(PrepList!#REF!="","",PrepList!#REF!) -> #REF! | N187: =IF(PrepList!#REF!="","",PrepList!#REF!) -> #REF!
B188: =IF(PrepList!#REF!="","",PrepList!#REF!) -> #REF! | C188: =_xlfn.XLOOKUP(D188,PrepList!F:F,PrepList!E:E) -> #REF! | D188: =IF(PrepList!#REF!="","",PrepList!#REF!) -> #REF! | E188: =IF(PrepList!#REF!="","",PrepList!#REF!) -> #REF! | F188: =IF(PrepList!#REF!="","",PrepList!#REF!) -> #REF! | G188: =IF(PrepList!#REF!="","",PrepList!#REF!) -> #REF! | H188: =IF(PrepList!#REF!="","",PrepList!#REF!) -> #REF! | I188: =IF(PrepList!#REF!="","",PrepList!#REF!) -> #REF! | J188: =IF(PrepList!#REF!="","",PrepList!#REF!) -> #REF! | L188: =IF(PrepList!#REF!="","",PrepList!#REF!) -> #REF! | N188: =IF(PrepList!#REF!="","",PrepList!#REF!) -> #REF!
B189: =IF(PrepList!#REF!="","",PrepList!#REF!) -> #REF! | C189: =_xlfn.XLOOKUP(D189,PrepList!F:F,PrepList!E:E) -> #REF! | D189: =IF(PrepList!#REF!="","",PrepList!#REF!) -> #REF! | E189: =IF(PrepList!#REF!="","",PrepList!#REF!) -> #REF! | F189: =IF(PrepList!#REF!="","",PrepList!#REF!) -> #REF! | G189: =IF(PrepList!#REF!="","",PrepList!#REF!) -> #REF! | H189: =IF(PrepList!#REF!="","",PrepList!#REF!) -> #REF! | I189: =IF(PrepList!#REF!="","",PrepList!#REF!) -> #REF! | J189: =IF(PrepList!#REF!="","",PrepList!#REF!) -> #REF! | L189: =IF(PrepList!#REF!="","",PrepList!#REF!) -> #REF! | N189: =IF(PrepList!#REF!="","",PrepList!#REF!) -> #REF!
B190: =IF(PrepList!#REF!="","",PrepList!#REF!) -> #REF! | C190: =_xlfn.XLOOKUP(D190,PrepList!F:F,PrepList!E:E) -> #REF! | D190: =IF(PrepList!#REF!="","",PrepList!#REF!) -> #REF! | E190: =IF(PrepList!#REF!="","",PrepList!#REF!) -> #REF! | F190: =IF(PrepList!#REF!="","",PrepList!#REF!) -> #REF! | G190: =IF(PrepList!#REF!="","",PrepList!#REF!) -> #REF! | H190: =IF(PrepList!#REF!="","",PrepList!#REF!) -> #REF! | I190: =IF(PrepList!#REF!="","",PrepList!#REF!) -> #REF! | J190: =IF(PrepList!#REF!="","",PrepList!#REF!) -> #REF! | L190: =IF(PrepList!#REF!="","",PrepList!#REF!) -> #REF! | N190: =IF(PrepList!#REF!="","",PrepList!#REF!) -> #REF!
B191: =IF(PrepList!#REF!="","",PrepList!#REF!) -> #REF! | C191: =_xlfn.XLOOKUP(D191,PrepList!F:F,PrepList!E:E) -> #REF! | D191: =IF(PrepList!#REF!="","",PrepList!#REF!) -> #REF! | E191: =IF(PrepList!#REF!="","",PrepList!#REF!) -> #REF! | F191: =IF(PrepList!#REF!="","",PrepList!#REF!) -> #REF! | G191: =IF(PrepList!#REF!="","",PrepList!#REF!) -> #REF! | H191: =IF(PrepList!#REF!="","",PrepList!#REF!) -> #REF! | I191: =IF(PrepList!#REF!="","",PrepList!#REF!) -> #REF! | J191: =IF(PrepList!#REF!="","",PrepList!#REF!) -> #REF! | L191: =IF(PrepList!#REF!="","",PrepList!#REF!) -> #REF! | N191: =IF(PrepList!#REF!="","",PrepList!#REF!) -> #REF!
B192: =IF(PrepList!#REF!="","",PrepList!#REF!) -> #REF! | C192: =_xlfn.XLOOKUP(D192,PrepList!F:F,PrepList!E:E) -> #REF! | D192: =IF(PrepList!#REF!="","",PrepList!#REF!) -> #REF! | E192: =IF(PrepList!#REF!="","",PrepList!#REF!) -> #REF! | F192: =IF(PrepList!#REF!="","",PrepList!#REF!) -> #REF! | G192: =IF(PrepList!#REF!="","",PrepList!#REF!) -> #REF! | H192: =IF(PrepList!#REF!="","",PrepList!#REF!) -> #REF! | I192: =IF(PrepList!#REF!="","",PrepList!#REF!) -> #REF! | J192: =IF(PrepList!#REF!="","",PrepList!#REF!) -> #REF! | L192: =IF(PrepList!#REF!="","",PrepList!#REF!) -> #REF! | N192: =IF(PrepList!#REF!="","",PrepList!#REF!) -> #REF!
B193: =IF(PrepList!#REF!="","",PrepList!#REF!) -> #REF! | C193: =_xlfn.XLOOKUP(D193,PrepList!F:F,PrepList!E:E) -> #REF! | D193: =IF(PrepList!#REF!="","",PrepList!#REF!) -> #REF! | E193: =IF(PrepList!#REF!="","",PrepList!#REF!) -> #REF! | F193: =IF(PrepList!#REF!="","",PrepList!#REF!) -> #REF! | G193: =IF(PrepList!#REF!="","",PrepList!#REF!) -> #REF! | H193: =IF(PrepList!#REF!="","",PrepList!#REF!) -> #REF! | I193: =IF(PrepList!#REF!="","",PrepList!#REF!) -> #REF! | J193: =IF(PrepList!#REF!="","",PrepList!#REF!) -> #REF! | L193: =IF(PrepList!#REF!="","",PrepList!#REF!) -> #REF! | N193: =IF(PrepList!#REF!="","",PrepList!#REF!) -> #REF!
B194: =IF(PrepList!#REF!="","",PrepList!#REF!) -> #REF! | C194: =_xlfn.XLOOKUP(D194,PrepList!F:F,PrepList!E:E) -> #REF! | D194: =IF(PrepList!#REF!="","",PrepList!#REF!) -> #REF! | E194: =IF(PrepList!#REF!="","",PrepList!#REF!) -> #REF! | F194: =IF(PrepList!#REF!="","",PrepList!#REF!) -> #REF! | G194: =IF(PrepList!#REF!="","",PrepList!#REF!) -> #REF! | H194: =IF(PrepList!#REF!="","",PrepList!#REF!) -> #REF! | I194: =IF(PrepList!#REF!="","",PrepList!#REF!) -> #REF! | J194: =IF(PrepList!#REF!="","",PrepList!#REF!) -> #REF! | L194: =IF(PrepList!#REF!="","",PrepList!#REF!) -> #REF! | N194: =IF(PrepList!#REF!="","",PrepList!#REF!) -> #REF!
B195: =IF(PrepList!#REF!="","",PrepList!#REF!) -> #REF! | C195: =_xlfn.XLOOKUP(D195,PrepList!F:F,PrepList!E:E) -> #REF! | D195: =IF(PrepList!#REF!="","",PrepList!#REF!) -> #REF! | E195: =IF(PrepList!#REF!="","",PrepList!#REF!) -> #REF! | F195: =IF(PrepList!#REF!="","",PrepList!#REF!) -> #REF! | G195: =IF(PrepList!#REF!="","",PrepList!#REF!) -> #REF! | H195: =IF(PrepList!#REF!="","",PrepList!#REF!) -> #REF! | I195: =IF(PrepList!#REF!="","",PrepList!#REF!) -> #REF! | J195: =IF(PrepList!#REF!="","",PrepList!#REF!) -> #REF! | L195: =IF(PrepList!#REF!="","",PrepList!#REF!) -> #REF! | N195: =IF(PrepList!#REF!="","",PrepList!#REF!) -> #REF!
B196: =IF(PrepList!#REF!="","",PrepList!#REF!) -> #REF! | C196: =_xlfn.XLOOKUP(D196,PrepList!F:F,PrepList!E:E) -> #REF! | D196: =IF(PrepList!#REF!="","",PrepList!#REF!) -> #REF! | E196: =IF(PrepList!#REF!="","",PrepList!#REF!) -> #REF! | F196: =IF(PrepList!#REF!="","",PrepList!#REF!) -> #REF! | G196: =IF(PrepList!#REF!="","",PrepList!#REF!) -> #REF! | H196: =IF(PrepList!K10="","",PrepList!K10) -> NM | I196: =IF(PrepList!L10="","",PrepList!L10) -> Passed | J196: =IF(PrepList!M10="","",PrepList!M10) -> Passed | L196: =IF(PrepList!#REF!="","",PrepList!#REF!) -> #REF! | N196: =IF(PrepList!#REF!="","",PrepList!#REF!) -> #REF!
...

Sheet Activity Tracker & Pipeline
A1: SLC Activity Tracker 2024 | D1: Applications | F1: Phone Screens | H1: Interviews | J1: Resume Subs | L1: Offers Accepted | M1: Decline Reasons
A2: Office | B2: Date | C2: # of recruiters | D2: Goal | E2: Attn | F2: Goal | G2: Attn | H2: Today | I2: Tomorrow | J2: Goal | K2: Attn | M2: Decline Reasons
A3: NSL | P3: Prepped | Q3: =R4+T4+V4+X4+Z4+AB4+AD4+AF4+AH4+AJ4+AL4+AN4 -> 496 | R3: A/C Mechanical Assembly | S3: BG Cleared | T3: B/D Mechanical Assembly | U3: BG Cleared | V3: A/C Materials | W3: BG Cleared | X3: B/D Materials | Y3: BG Cleared | Z3: A/C Rack Assembly | AA3: BG Cleared | AB3: B/D Rack Assembly | AC3: BG Cleared | AD3: IT Support Technician | AE3: BG Cleared | AF3: Delivery Business Systems Analyst | AG3: BG Cleared | AH3: B/D Quality | AI3: BG Cleared | AJ3: A/C Test Operator | AK3: BG Cleared | AL3: A/C Debug | AM3: BG Cleared | AN3: B/D Debug Tech 4 | AO3: BG Cleared
A4: WVC | P4: Cleared | Q4: =S4+U4+W4+Y4+AA4+AC4+AE4+AG4+AI4+AK4+AM4+AO4 -> 238 | R4: 306 | S4: 149 | T4: 130 | U4: 61 | V4: 15 | W4: 10 | X4: 19 | Y4: 8 | Z4: 12 | AA4: 4 | AB4: 12 | AC4: 4 | AD4: 0 | AE4: 0 | AF4: 0 | AG4: 0 | AH4: 0 | AI4: 0 | AJ4: 0 | AK4: 0 | AL4: 1 | AM4: 1 | AN4: 1 | AO4: 1 | AP4: 3 | AQ4: 1 | AR4: 2 | AS4: 2 | AT4: 0 | AU4: 0 | AV4: 0 | AW4: 0 | AX4: 0 | AY4: 0 | AZ4: 0 | BA4: 0
A5: WJ | P5: Updated | Q5: 46197
A6: TOTAL | C6: =SUM(C2:C5) -> 0 | D6: =SUM(D2:D5) -> 0 | E6: =SUM(E2:E5) -> 0 | F6: =SUM(F2:F5) -> 0 | G6: =SUM(G2:G5) -> 0 | H6: =SUM(H2:H5) -> 0 | I6: =SUM(I2:I5) -> 0 | J6: =SUM(J2:J5) -> 0 | ... L6: =SUM(L2:L5) -> 0
A9: Date Last Posted | C9: WVC | D9: 45985 | E9: 45986 | F9: 45987 | G9: 45988 | H9: 45989 | K9: A Roster Starts
C10: QC Inspector - Days | D10: 5 | K10: B Roster Starts
C11: QC Inspector - Nights | D11: 0
C12: 1st shift assembly | D12: 0
C13: 3rd shift assembly | D13: 0
A14: Date Last Posted | C14: WJ
C15: 3rd shift assembly | D15: 0
A18: Date Last Posted | C18: NSL
B19: Day - Warehouse | D19: 0
B20: Grave - Warehouse | D20: 0
B21: Grave - Quality Control | D21: 0
B22: Day - Quality Control | D22: 0
C24: Applies | D24: =SUM(D10:D23) -> 5 | E24: =SUM(E10:E23) -> 0 | F24: =SUM(F10:F23) -> 0 | G24: =SUM(G10:G23) -> 0 | H24: =SUM(H10:H23) -> 0 | I24: =SUM(I10:I23) -> 0 | J24: =SUM(J10:J23) -> 0
D25: by 5pm

Sheet PrepList
A1: Date | B1: Last Contacted | C1: Contacted | D1: Language | E1: Employee Name (must match Avionte) | F1: Talent ID | G1: Phone | H1: Shift Preference | I1: Position | J1: Office | K1: Recruiter | L1: BG? | M1: DT? | N1: FLEX Doc Sent | O1: Attended Mini Orientation | P1: Notes
A2: 45797 | B2: 46260 | C2: Contacted | D2: Spanish | E2: Doraxci Gonzalez | F2: 177671254 | G2: 3856289600 | H2: Day Shift | I2: Mechanical Assembly | J2: WJ | K2: FZ | L2: Pending | N2: Passed | O2: Yes | P2: Confirmed on 8/26 she is still interested
A3: 45869 | B3: 46260 | C3: Contacted | D3: Spanish | E3: Maralis Mendoza | F3: 198173510 | G3: 3852164295 | H3: Day Shift | I3: Mechanical Assembly | J3: WJ | K3: BL | L3: Passed | M3: Passed | N3: Passed | P3: Confirmed on 8/26 she is still interested
A4: 45876 | B4: 46260 | C4: Contacted | D4: Spanish | E4: Edna Dominguez | F4: 148926496 | G4: 8019185846 | H4: Night Shift | I4: Mechanical Assembly | J4: WVC | K4: CE | L4: Passed | M4: Passed | N4: Passed | P4: She stated she wont be in Utah for a few months?
A5: 45876 | B5: 46260 | C5: Contacted | D5: Spanish | E5: Amayrany Hernandez | F5: 198303055 | G5: 3855410937 | H5: Night Shift | I5: Mechanical Assembly | J5: WVC | K5: CE | L5: Passed | M5: Passed | N5: Passed | P5: Confirmed on 8/26 she is still interested
A6: 45877 | B6: 46260 | C6: Contacted | D6: Spanish | E6: Aracely Hernandez | F6: 198318924 | G6: 4357141187 | H6: Night Shift | I6: Mechanical Assembly | J6: WVC | K6: CE | L6: Passed | M6: Passed | N6: Passed
A7: 45880 | B7: 46260 | C7: Contacted | D7: Spanish | E7: Snayder Pongo | F7: 198237668 | G7: 3854883070 | H7: Day Shift | I7: Mechanical Assembly | J7: WJ | K7: NM | L7: Passed | M7: Passed | N7: Passed
A8: 45881 | B8: 46260 | C8: Contacted | D8: Spanish | E8: Yennifer Hernandez | F8: 186325204 | G8: 8015094766 | H8: Day Shift | I8: Mechanical Assembly | J8: WJ | K8: BL | L8: Passed | M8: Passed | N8: Passed
A9: 45881 | B9: 46260 | C9: Contacted | D9: Spanish | E9: Norelkys Gallardo | F9: 185565315 | G9: 3855907316 | H9: Day Shift | I9: Mechanical Assembly | J9: WJ | K9: BL | L9: Passed | M9: Passed | N9: Passed
A10: 45887 | B10: 46260 | C10: Contacted | D10: Spanish | E10: Aura Rivas | F10: 177626645 | G10: 3322563395 | H10: Night Shift | I10: Mechanical Assembly | J10: WJ | K10: NM | L10: Passed | M10: Passed | N10: Passed | O10: Yes | P10: Confirmed on 8/26 she is still interested
A11: 45888 | B11: 46260 | C11: Contacted | D11: Spanish | E11: Alber Carillo | F11: 182934778 | G11: 4352007063 | H11: Day Shift | I11: Mechanical Assembly | J11: NSL | K11: DR | L11: Passed | M11: Passed | N11: Passed | O11: Pending
A12: 45888 | B12: 46260 | C12: Contacted | D12: Spanish | E12: Mary Andrade | F12: 198304520 | G12: 3852674145 | H12: Day Shift | I12: Mechanical Assembly | J12: WVC | K12: CE | L12: Passed | M12: Passed | N12: Passed
A13: 45889 | B13: 46260 | C13: Contacted | D13: Spanish | E13: Yoseani Contreras | F13: 198457422 | G13: 5517991219 | H13: Night Shift | I13: Mechanical Assembly | J13: WVC | K13: CE | L13: Passed | M13: Passed | N13: Passed | O13: Pending
A14: 01/16/226 | B14: 46260 | C14: Contacted | D14: Spanish | E14: Irene Guerrero | F14: 176593378 | G14: 3855894411 | H14: Day Shift | I14: Mechanical Assembly | J14: WJ | K14: NM | L14: Passed | M14: Passed | N14: Passed | O14: Pending
B15: 46265 | C15: Contacted | D15: Spanish | E15: Diego Gomez | F15: 186547714 | G15: 9283237807 | H15: Day Shift | I15: Mechanical Assembly | J15: NSL | K15: DR | L15: Passed | M15: Passed | N15: Passed | O15: Pending
B16: 46265 | C16: Contacted | D16: Spanish | E16: Genesis Gonzales | F16: 155192157 | G16: 8018312018 | H16: Night Shift | I16: Mechanical Assembly | J16: NSL | K16: DR | L16: Not Ran | M16: Passed | N16: Sent | O16: Pending | P16: Confirmed on 9/1 she is stil interested
B17: 46265 | C17: Contacted | D17: Spanish | E17: Erika Beltran | F17: 215164885 | G17: 3854919576 | H17: Night Shift | I17: Mechanical Assembly | J17: NSL | K17: DR | L17: Not Ran | M17: Passed | N17: Sent | O17: Pending
B18: 46265 | C18: Contacted | D18: Spanish | E18: Adriana Gonzales | F18: 216395703 | G18: 3852964862 | H18: Day Shift | I18: Mechanical Assembly | J18: NSL | K18: DR | L18: Pending | N18: Passed | O18: Pending
B19: 46266 | C19: Contacted | D19: Spanish | E19: Maira Aray | F19: 167482313 | G19: 8014036011 | H19: Day Shift | I19: Mechanical Assembly | J19: NSL | K19: DR | L19: Not Ran | N19: Sent | O19: Pending
B20: 46266 | C20: Contacted | D20: Spanish | E20: Francisca Rodriguez | F20: 216398767 | G20: 8016001096 | H20: Day Shift | I20: Mechanical Assembly | J20: NSL | K20: DR | L20: Pending | N20: Passed | O20: Pending
B21: 46266 | C21: Contacted | D21: Spanish | E21: Edgar Blanco | F21: 198454505 | G21: 3855410257 | H21: Day Shift | I21: Mechanical Assembly | J21: WJ | K21: NM | L21: Passed | M21: Passed | N21: Passed | O21: Yes | P21: Phone# no longer valid
B22: 46266 | C22: Contacted | D22: Spanish | E22: Joaquina mAlvarado | F22: 182803870 | G22: 3855767303 | H22: Day Shift | I22: Mechanical Assembly | J22: WVC | K22: AR | L22: Passed | M22: Passed | N22: Passed
B23: 46266 | C23: Contacted | D23: Spanish | E23: Susana Medina | F23: 95712795 | G23: (385) 775-3179 | H23: Day Shift | I23: Mechanical Assembly | J23: WJ | K23: BL | L23: Passed | M23: Passed | N23: Passed | P23: Confirmed on 9/1 she is still interested
B24: 46266 | C24: Contacted | D24: Spanish | E24: Greisibel Reyes | F24: 187283462 | G24: 3076775835 | H24: Day Shift | I24: Mechanical Assembly | J24: WJ | K24: BL | L24: Passed | M24: Passed | N24: Passed
C25: Contacted | D25: English | E25: Chad Candland | F25: 167453188 | G25: 8015746280 | H25: Night Shift | I25: Mechanical Assembly | J25: NSL | K25: GKW | L25: Passed | M25: Passed | N25: Passed
B26: 46266 | C26: Contacted | D26: Spanish | E26: Fainoly Nino | F26: 198115241 | G26: 8012443795 | H26: Day Shift | I26: Mechanical Assembly | J26: NSL | K26: DG | L26: Pending | M26: Passed | N26: Passed
B27: 46269 | C27: Contacted | D27: Spanish | E27: Jahiro Salas | F27: 198477793 | G27: 8016618133 | H27: Day Shift | I27: Mechanical Assembly | J27: NSL | K27: DG | L27: Passed | M27: Passed | N27: Passed
B28: 46269 | C28: Contacted | D28: Spanish | E28: ELIO PORTILLA | G28: (801) 895-6980 | H28: Day Shift | I28: Mechanical Assembly | J28: NSL | K28: DR | L28: Passed | M28: Passed | N28: Passed
B29: 46269 | C29: Contacted | D29: Bilingual | E29: Martha Salvador Trejo | F29: 199551858 | G29: 3853430317 | H29: Day Shift | I29: Mechanical Assembly | J29: WVC | K29: CE | L29: Passed | M29: Passed | N29: Passed
B30: 46269 | C30: Contacted | D30: Spanish | E30: Luz Ospina | F30: 186544458 | G30: (609) 516-2765 | H30: Day Shift | I30: Mechanical Assembly | J30: WVC | K30: CE
B31: 46269 | C31: Contacted | D31: Bilingual | E31: Rocio Rodriguez | G31: 801-7219587 | H31: Day Shift | J31: NSL
B32: 46269 | C32: Contacted | D32: Spanish | E32: Maria Linares | F32: 155478795 | G32: 3852610893 | H32: Day Shift | I32: Mechanical Assembly | J32: WJ | K32: NM | L32: Passed | M32: Passed | N32: Passed
B33: 46269 | C33: Contacted | D33: Spanish | E33: Dilianny Delsie | F33: 177942733 | G33: 8015849797 | H33: Day Shift | I33: Mechanical Assembly | J33: NSL | K33: DR | L33: Pending | M33: Passed | N33: Passed
B34: 46269 | C34: Contacted | D34: Spanish | E34: Katty Rossell | F34: 216398708 | G34: 5512025893 | H34: Day Shift | I34: Mechanical Assembly | J34: NSL | K34: DR | L34: Not Ran | N34: Passed
B35: 46269 | C35: Contacted | D35: Spanish | E35: Marialex Parajo | F35: 191900159 | G35: 3852522378 | H35: Day Shift | I35: Mechanical Assembly | J35: NSL | K35: DR | L35: Passed | M35: Passed | N35: Sent
B36: 46273 | C36: Contacted | D36: English | E36: Tyrone Scott | F36: 218580424 | G36: 8016669504 | H36: Night Shift | I36: Mechanical Assembly | J36: NSL | K36: GKW | N36: Sent | P36: Interested as of 9/9/26
A37: 46072 | B37: 46273 | C37: Contacted | D37: Spanish | E37: Gabriela Fernandez | F37: 144684733 | G37: 3852377965 | H37: Day Shift | I37: Mechanical Assembly | J37: WJ | K37: BL | L37: Passed | M37: Passed | N37: Passed
A38: 46072 | B38: 46273 | C38: Contacted | D38: Spanish | E38: Anabelis Peraza | F38: 139332894 | G38: 3854572418 | H38: Night Shift | I38: Materials | J38: WJ | K38: FZ | L38: Passed | M38: Passed | N38: Passed
A39: 46072 | B39: 46273 | C39: Contacted | D39: Spanish | E39: Eva Ramirez | F39: 218508261 | G39: 8018280334 | H39: Day Shift | I39: Mechanical Assembly | J39: WJ | K39: BL | L39: Passed | M39: Passed | N39: Passed | P39: Interested as of 9/9
A40: 46072 | B40: 46273 | C40: Contacted | D40: Spanish | E40: Ricardo Perea Vera | F40: 218637517 | G40: 3858314755 | H40: Night Shift | I40: Mechanical Assembly | J40: WVC | K40: SM | L40: Passed | M40: Passed | N40: Passed | P40: Interested as of 9/9
...

Sheet Mini Orientation
A1: Thursday 8/6/26 @ 4pm | B1: DO NOT ADD EXTRA ROWS!!!!!!!! | C1: SPANISH ONLY | D1: NO MORE THAN 20 PER CLASS
A2: SSN # | B2: Employe Name Must Match Avionte | C2: Bold ID | D2: Phone | E2: Recruiter | F2: Shift Pref | G2: Arrived | H2: Placed | I2: Notes
B3: Massiel Zabala | C3: 112007733 | D3: 801-564-0825 | E3: BL | F3: Days | G3: Yes | I3: C-shift
A4: 892-08-6999 | B4: Jesus Antonio Villareal Blanco | C4: 115655543 | D4: (385) 242-0947 | E4: FZ | F4: Nights | G4: No
B5: Andres Caruci | C5: 226544093 | D5: 3038886330 | E5: BL | F5: Days | G5: Yes | I5: C-shift
B6: Maribeth Castillo | C6: 190427449 | D6: 2678893261 | E6: DR | F6: Days | G6: Yes | I6: C- Shift (mechanical Assembly)
B7: Gabriella Martinez | C7: 95676314 | D7: (801) 815-5063 | E7: DR | F7: Days | G7: Yes
A8: 721-67-3496 | B8: Jhoseiny Gonzalez | C8: 209195517 | D8: 3852821517 | E8: NM | F8: Nights | G8: Yes | H8: Yes
A9: 122-77-9660 | B9: Jossellyne Orellana | C9: 115744726 | D9: 3474758685 | E9: NM | F9: Days | G9: Yes
A11: 288-45-9300 | B11: Richard Rios | C11: 146966394 | D11: 3855569276 | E11: FZ | F11: Days | G11: Yes
A12: 065-21-3194 | B12: Julio Perez Olivar | C12: 139298190 | D12: 801-903-0227 | E12: RP | F12: Days | G12: Yes | I12: C-Shift (Warehouse)
A13: 647-98-4023 | B13: Ilia A Romero | C13: 228805148 | D13: 3853026775 | E13: FZ | F13: Days | G13: Late
A20: Friday 8/7/26 @ 4pm | B20: DO NOT ADD EXTRA ROWS!!!!!!!! | C20: SPANISH ONLY | D20: NO MORE THAN 20 PER CLASS
A21: SSN # | B21: Employe Name Must Match Avionte | C21: Bold ID | D21: Phone | E21: Recruiter | F21: Shift Pref | G21: Arrived | H21: Placed | I21: Notes
A22: 022-13-1925 | B22: Teresa Hernandez Navarro | C22: 121712371 | D22: 8018153036 | E22: GKW | F22: Days | G22: Yes
B23: Alicia S Ruiz | C23: 217675488 | D23: 3855482730 | E23: NM | F23: Days | G23: Yes
A24: 647-76-9145 | B24: Ali M Osman | C24: 95659911 | D24: (801) 953-7958 | E24: GKW | F24: Days | I24: Rescheduled to Wed
A25: 647-98-4023 | B25: Ilia A Romero | C25: 228805148 | D25: 3853026775 | E25: FZ | F25: Days | G25: Yes
B26: Kahirys Maria Melendez | C26: 120736470 | D26: 3854362422 | E26: NM | F26: Days | G26: Yes
A27: 172-02-3958 | B27: Anais Faria | C27: 227227008 | D27: 3854183056 | E27: FZ | F27: Days | G27: Yes
B28: Eubbeidys E Gonzalez | C28: 224736795 | D28: 9294971616 | E28: NM | F28: Days | G28: Yes
B29: Maria Reyes | C29: 225305567 | D29: 3465463544 | E29: NM | F29: Days | G29: Yes
A30: 136-85-9076 | B30: Nayvir Medina | C30: 230183012 | D30: 385 424 2946 | E30: NM | F30: Days | G30: Yes
A31: 670-50-3472 | B31: Estersi Cacciatore | C31: 229512238 | D31: 8019704852 | E31: BL | F31: Days
B32: Brandon Gonzalez | I32: A shift preferably
A33: 388-71-5477 | B33: Valeria Sandoval | C33: 215128480 | D33: 5598714822 | E33: EP | F33: Nights | G33: Yes
B34: Rocio Rodriguez | C34: 199432485 | D34: +1 385 405 5400 | E34: CN | F34: Days | G34: Yes
A35: 318-95-5312 | B35: Gabriela Aguilar | C35: 230399050 | D35: 3855089565 | E35: NM | F35: Days | G35: Yes
B36: Juan Pablo Saenz | C36: 230400373 | D36: 8016046577 | E36: BL | F36: Days
B37: Ivan Diego Chirinos | C37: 230400380 | D37: 3854348866 | E37: BL | F37: Days
B38: Andris Camargo | C38: 230208470 | D38: 8015741147 | E38: NM | F38: Days | G38: Yes
B39: Ybyairy Leon | C39: 145002751 | D39: 3853387095 | E39: NM | F39: Days | G39: Yes
B40: Karianna Melendez | C40: 230401816 | D40: 8016349052 | E40: NM | F40: Days | G40: Yes
A41: 646-82-3613 | B41: Brandon Gonzalez | C41: 228896924 | D41: 385 418 7532 | E41: NM | F41: Nights
B42: Jorge Valdez | C42: 95682428 | D42: (386) 643-9100 | E42: FZ | F42: Days | I42: C shift
A43: Saturday 8/8/26 @ 4pm | B43: DO NOT ADD EXTRA ROWS!!!!!!!! | C43: SPANISH ONLY | D43: NO MORE THAN 20 PER CLASS
A44: SSN # | B44: Employe Name Must Match Avionte | C44: Bold ID | D44: Phone | E44: Recruiter | F44: Shift Pref | G44: Arrived | H44: Placed | I44: Notes
A45: 204734859 | B45: Johny Kourkounian | C45: 223463547 | D45: 8013478780 | E45: JM | F45: Days
A46: 820038147 | B46: Claudia La Rosa Quispe | C46: 185852924 | D46: 3854794854 | E46: JY | F46: B | I46: B Shift
A47: 354-23-8705 | B47: Alejandra C Valdez | C47: 114717224 | D47: 3852967913 | E47: FZ | F47: A | I47: A shift
...

Sheet Orientations Old
B1: Tuesday 7/29/25 @2pm | C1: SPANISH | D1: NO MORE THAN 20 | F1: Nights | G1: Arrived | H1: Offer | I1: Notes - A Roster or B Roster (A = English/Bilingual and 1+ year exp) (B = Spanish and no exp.)
B2: Employe Name | C2: Employee # | D2: Phone | E2: Recruiter | F2: Shift Pref
B3: Joraima Soto | C3: 186324826 | D3: 3854904410 | E3: FZ | F3: Materials | G3: Yes | H3: Yes
B4: Maria Rodriguez | C4: 176583998 | D4: (385) 280-6295 | E4: DG | F4: A/C (Day) | G4: Yes | H4: Yes
B5: Fatima Briceno | C5: 187997721 | D5: 8019150994 | E5: NM | F5: B/D (Night | G5: Yes | H5: Yes
B6: Anyela Blanco | C6: 190324150 | D6: 8013309103 | E6: NM | F6: B/D (Night | G6: Yes | H6: Yes
B7: Leomaris Guzman | C7: 194816575 | D7: 3854361573 | E7: NM | F7: B/D (Night | G7: Yes | H7: Yes
B8: Badrolilia Peraza | C8: 101885257 | D8: 8014256308 | E8: NM | F8: B/D (Night | G8: Yes | H8: no | I8: Unable to contact
B9: Jonathan Arellanes | C9: 194528743 | D9: 3854238506 | E9: NM | F9: B/D (Night | G9: No
B10: Tairy Angulo | C10: 181369439 | D10: 3855065808 | E10: NM | F10: A/C (Day) | G10: Yes | H10: Yes
B11: Neis Pirela | C11: 176962718 | D11: 8012054460 | E11: NM | F11: A/C (Day) | G11: Yes | H11: Yes
B12: SimonRomero | C12: 117084972 | D12: 3852273302 | E12: DG | F12: A/C (Day) | G12: Yes | H12: Yes
B13: Lilibeth Roman | C13: 168124100 | D13: 3852295061 | E13: NM | F13: B/D (Night | G13: yes | H13: Yes
B14: Luis Garcia | C14: 194760398 | D14: 3853147960 | E14: NM | F14: A/C (Day) | G14: Rescheduled | I14: 7 mins late
B15: Romer Magdaniel | C15: 146674951 | D15: 9294247309 | E15: NM | F15: A/C (Day) | G15: yes | H15: Yes
B16: Enyaj Garcia | C16: 193856840 | D16: 8018094198 | E16: NM | F16: A/C (Day) | G16: yes | H16: Yes
B17: Yarelis Delgado | C17: 194501314 | D17: 3462439741 | E17: NM | F17: A/C (Day) | G17: yes | H17: Yes
B18: Jarol Martinez | C18: 193852264 | D18: 8016349786 | E18: FZ | F18: B/D (Night | G18: yes | H18: Yes
B19: Yorleny Luna | C19: 197892151 | D19: 3855735944 | E19: NM | F19: B/D (Night | G19: yes | H19: Yes
B20: Javier Calderon | C20: 193880878 | D20: 8013817589 | E20: BL | F20: A/C (Day) | G20: yes | H20: Yes
B21: Leticia Lopez | C21: 197900170 | D21: 385 484 2641 | E21: DG | F21: A/C (Day) | G21: yes | H21: No | I21: Not enough english
B22: Alma Hernandez | C22: 193852260 | D22: 8018757583 | E22: NM | F22: A/C (Day) | G22: yes | H22: Yes
B23: Joel Martinez | C23: 186524512 | D23: 3854908227 | E23: NM | F23: B/D (Night | G23: yes | H23: Yes
B24: Marvin Delgado | C24: 186627342 | D24: 3854566241 | E24: NM | F24: B/D (Night | G24: yes | H24: Yes
B25: Wednesday 7/30/25 @1 pm | C25: SPANISH | D25: NO MORE THAN 20 | G25: Arrived | H25: Offer | I25: Notes - A Roster or B Roster (A = English/Bilingual and 1+ year exp) (B = Spanish and no exp.)
B26: Employe Name | C26: Employee # | D26: Phone | E26: Recruiter | F26: Shift Pref
B27: Maira Querales | C27: 152806550 | D27: 3856958686 | E27: NM | F27: A/C (Day) | G27: yes | H27: Yes | I27: B
B28: Maria Martinez | C28: 198091228 | D28: 4698940779 | E28: DG | F28: B/D (Night | G28: yes | H28: Yes
B29: William Marrufo | C29: 198091268 | D29: 8016445290 | E29: DG | F29: B/D (Night | G29: yes | H29: Yes
B30: Liduvina Aguilera | C30: 194519751 | D30: 3854650569 | E30: FZ | F30: A/C (Day) | G30: yes | H30: Yes
B31: Maria Lorena Mendez | C31: 194519834 | D31: 3854650569 | E31: FZ | F31: A/C (Day) | G31: yes | H31: Yes
B32: Erwin Pinzon | C32: 198098739 | D32: 3852859222 | E32: NM | F32: A/C (Day) | G32: yes | H32: No | I32: B unable to contact
B33: Ana Rivero | C33: 198038100 | D33: 7578312339 | E33: DG | F33: A/C (Day) | G33: yes | H33: Yes
B34: Liz Ascencio | C34: 177677124 | D34: 8012055313 | E34: CE | F34: A/C (Day) | G34: yes | H34: Yes
B35: Priscilla Salgado | C35: 198119474 | D35: 3852680226 | E35: DG | F35: B/D (Night
B36: Alexander Molina | C36: 198115158 | D36: 3853145049 | E36: FZ | F36: A/C (Day) | G36: yes | H36: Yes | I36: B
B37: Joselyn Rivas | C37: 177664785 | D37: 3852165535 | E37: FZ | F37: A/C (Day) | G37: yes | H37: No | I37: B
B38: Porfirio Magana Diaz | C38: 95708871 | D38: (801) 935-7631 | E38: FZ | F38: A/C (Day) | G38: yes | H38: Yes | I38: A
B39: Sharedt Alfaro | C39: 198119624 | D39: 9145254472 | E39: NM | F39: B/D (Night | G39: yes | H39: Yes
B40: Oscar Sanchez | C40: 198085680 | D40: 8017555395 | E40: BL | F40: B/D (Night | G40: yes | H40: Yes | I40: B
...

Sheet Hired
A1: Date | B1: Last Contacted | C1: Status | D1: Language | E1: Employee Name (must match Avionte) | F1: Talent ID | G1: Phone | H1: Shift Preference | I1: Position | J1: Office | K1: Recruiter | L1: BG? | M1: DT? | N1: FLEX Doc Sent | O1: Attended Mini Orientation | P1: Notes
A2: 46128 | D2: Spanish | E2: Joanna Munoz | F2: 216559414 | G2: 3854439875 | H2: Night Shift | I2: Mechanical Assembly | J2: WVC | K2: JY | L2: Passed | M2: Passed | N2: Passed | O2: Yes
A3: 46125 | D3: Spanish | E3: Laura Ambriz | F3: 96619838 | G3: 3853370012 | H3: Day Shift | I3: Mechanical Assembly | J3: WVC | K3: JY | L3: Passed | M3: Passed | N3: Passed
A4: 46125 | D4: Spanish | E4: Hildemaro Vargas | F4: 221840574 | G4: 3854050571 | H4: Night Shift | I4: Mechanical Assembly | J4: WJ | K4: NM | L4: Pending | M4: Passed | N4: Passed | O4: Yes
A5: 46122 | D5: Spanish | E5: Desiree Roa | F5: 199708572 | G5: 3854363656 | H5: Night Shift | I5: Mechanical Assembly | J5: WVC | K5: JY | L5: Pending | M5: Passed | N5: Passed | O5: Yes
A6: 46112 | D6: Bilingual | E6: Alondra Portillo | F6: 134090007 | G6: 801 205-1714 | H6: Night Shift | I6: Mechanical Assembly | J6: WJ | K6: NM | L6: Passed | M6: Passed | N6: Passed | O6: Yes
A7: 46112 | D7: Spanish | E7: Franklin Marroquin | F7: 221153634 | G7: 8016697856 | H7: Night Shift | I7: Mechanical Assembly | J7: WJ | K7: NM | L7: Passed | M7: Passed | N7: Passed | O7: Yes
A8: 46112 | D8: Spanish | E8: Lina Mendoza Mantilla | F8: 129270240 | G8: 7153106810 | H8: Night Shift | I8: Mechanical Assembly | J8: WVC | K8: HB | L8: Pending | M8: Passed | N8: Passed
A9: 46111 | D9: Spanish | E9: Orlando Herrera | F9: 146893715 | G9: 3854143049 | H9: Night Shift | I9: Mechanical Assembly | J9: WJ | K9: NM | L9: Pending | M9: Passed | N9: Passed | O9: Yes
A10: 46105 | D10: Spanish | E10: Cesar Paredes | F10: 220962745 | G10: (385) 445-0455 | H10: Night Shift | I10: Mechanical Assembly | J10: WJ | K10: NM | L10: Passed | M10: Passed | N10: Passed | O10: Yes
A11: 46022 | D11: Spanish | E11: Maira Colmenarez | F11: 182102784 | G11: 8529853652 | H11: Night Shift | I11: Mechanical Assembly | J11: WJ | K11: NM | L11: Passed | M11: Passed | N11: Passed | O11: Yes
A12: 46097 | D12: Spanish | E12: Robinson Portillo | F12: 220528859 | G12: 3855036486 | H12: Night Shift | I12: Mechanical Assembly | J12: WJ | K12: NM | L12: Pending | M12: Passed | N12: Passed | O12: Yes
A13: 46091 | D13: Spanish | E13: Eric Ahumada | F13: 219148124 | G13: 4359383183 | H13: Day Shift | I13: Mechanical Assembly | J13: WJ | K13: NM | L13: Pending | M13: Passed | N13: Passed
A14: 46090 | D14: Spanish | E14: Karla Saras | F14: 194460546 | G14: 8019008532 | H14: Night Shift | I14: Mechanical Assembly | J14: WJ | K14: NM | L14: Passed | M14: Passed | N14: Passed | O14: Yes
A15: 46085 | D15: Spanish | E15: Glencis Pacheco | F15: 219091840 | G15: 3853790835 | H15: Day Shift | I15: Mechanical Assembly | J15: WJ | K15: NM | L15: Pending | M15: Passed | N15: Passed | O15: Yes
