Workbook

Sheet Activity Tracker & Pipeline
A1: SLC Activity Tracker 2024 | D1: Applications | F1: Phone Screens | H1: Interviews | J1: Resume Subs | L1: Offers Accepted | M1: Decline Reasons
A2: Office | B2: Date | C2: # of recruiters | D2: Goal | E2: Attn | F2: Goal | G2: Attn | H2: Today | I2: Tomorrow | J2: Goal | K2: Attn | M2: Decline Reasons
A3: =Scorecard!$H$4 -> NSL | P3: Prepped | Q3: =COUNTIFS('1.PrepList'!$I$2:$I$1500,"<>",'1.PrepList'!$B$2:$B$1500,"<>Yes") -> 512 | R3: A/C Mechanical Assembly | S3: BG Cleared | T3: B/D Mechanical Assembly | U3: BG Cleared | V3: A/C Materials | W3: BG Cleared | X3: B/D Materials | Y3: BG Cleared | Z3: A/C Rack Assembly | AA3: BG Cleared | AB3: B/D Rack Assembly | AC3: BG Cleared | AD3: IT Support Technician | AE3: BG Cleared | AF3: Delivery Business Systems Analyst | AG3: BG Cleared | AH3: B/D Quality | AI3: BG Cleared | AJ3: A/C Test Operator | AK3: BG Cleared | AL3: A/C Debug | AM3: BG Cleared | AN3: B/D Debug Tech 4 | AO3: BG Cleared
A4: =Scorecard!$H$5 -> WVC | P4: Cleared | Q4: =COUNTIFS('1.PrepList'!$O$2:$O$1500,"Passed",'1.PrepList'!$B$2:$B$1500,"<>Yes") -> 247 | R4: =SUMPRODUCT(COUNTIFS('1.PrepList'!$L$2:$L$1500,"Mechanical Assembly",'1.PrepList'!$K$2:$K$1500,{"A/C","A","C"},'1.PrepList'!$B$2:$B$1500,"<>Yes")) -> 309 | S4: =SUMPRODUCT(COUNTIFS('1.PrepList'!$L$2:$L$1500,"Mechanical Assembly",'1.PrepList'!$K$2:$K$1500,{"A/C","A","C"},'1.PrepList'!$O$2:$O$1500,"Passed",'1.PrepList'!$B$2:$B$1500,"<>Yes")) -> 152 | T4: =SUMPRODUCT(COUNTIFS('1.PrepList'!$L$2:$L$1500,"Mechanical Assembly",'1.PrepList'!$K$2:$K$1500,{"B/D","B","D"},'1.PrepList'!$B$2:$B$1500,"<>Yes")) -> 133 | U4: =SUMPRODUCT(COUNTIFS('1.PrepList'!$L$2:$L$1500,"Mechanical Assembly",'1.PrepList'!$K$2:$K$1500,{"B/D","B","D"},'1.PrepList'!$O$2:$O$1500,"Passed",'1.PrepList'!$B$2:$B$1500,"<>Yes")) -> 63 | V4: =SUMPRODUCT(COUNTIFS('1.PrepList'!$L$2:$L$1500,"Materials",'1.PrepList'!$K$2:$K$1500,{"A/C","A","C"},'1.PrepList'!$B$2:$B$1500,"<>Yes")) -> 15 | W4: =SUMPRODUCT(COUNTIFS('1.PrepList'!$L$2:$L$1500,"Materials",'1.PrepList'!$K$2:$K$1500,{"A/C","A","C"},'1.PrepList'!$O$2:$O$1500,"Passed",'1.PrepList'!$B$2:$B$1500,"<>Yes")) -> 10 | X4: =SUMPRODUCT(COUNTIFS('1.PrepList'!$L$2:$L$1500,"Materials",'1.PrepList'!$K$2:$K$1500,{"B/D","B","D"},'1.PrepList'!$B$2:$B$1500,"<>Yes")) -> 18 | Y4: =SUMPRODUCT(COUNTIFS('1.PrepList'!$L$2:$L$1500,"Materials",'1.PrepList'!$K$2:$K$1500,{"B/D","B","D"},'1.PrepList'!$O$2:$O$1500,"Passed",'1.PrepList'!$B$2:$B$1500,"<>Yes")) -> 7 | Z4: =SUMPRODUCT(COUNTIFS('1.PrepList'!$L$2:$L$1500,"Rack Assembly",'1.PrepList'!$K$2:$K$1500,{"A/C","A","C"},'1.PrepList'!$B$2:$B$1500,"<>Yes")) -> 11 | AA4: =SUMPRODUCT(COUNTIFS('1.PrepList'!$L$2:$L$1500,"Rack Assembly",'1.PrepList'!$K$2:$K$1500,{"A/C","A","C"},'1.PrepList'!$O$2:$O$1500,"Passed",'1.PrepList'!$B$2:$B$1500,"<>Yes")) -> 4 | AB4: =SUMPRODUCT(COUNTIFS('1.PrepList'!$L$2:$L$1500,"Rack Assembly",'1.PrepList'!$K$2:$K$1500,{"B/D","B","D"},'1.PrepList'!$B$2:$B$1500,"<>Yes")) -> 12 | AC4: =SUMPRODUCT(COUNTIFS('1.PrepList'!$L$2:$L$1500,"Rack Assembly",'1.PrepList'!$K$2:$K$1500,{"B/D","B","D"},'1.PrepList'!$O$2:$O$1500,"Passed",'1.PrepList'!$B$2:$B$1500,"<>Yes")) -> 4 | AD4: =COUNTIFS('1.PrepList'!$L$2:$L$1500,"IT Support Technician",'1.PrepList'!$B$2:$B$1500,"<>Yes") -> 0 | AE4: =COUNTIFS('1.PrepList'!$L$2:$L$1500,"IT Support Technician",'1.PrepList'!$O$2:$O$1500,"Passed",'1.PrepList'!$B$2:$B$1500,"<>Yes") -> 0 | AF4: =COUNTIFS('1.PrepList'!$L$2:$L$1500,"Delivery Business Systems Analyst",'1.PrepList'!$B$2:$B$1500,"<>Yes") -> 0 | AG4: =COUNTIFS('1.PrepList'!$L$2:$L$1500,"Delivery Business Systems Analyst",'1.PrepList'!$O$2:$O$1500,"Passed",'1.PrepList'!$B$2:$B$1500,"<>Yes") -> 0 | AH4: =SUMPRODUCT(COUNTIFS('1.PrepList'!$L$2:$L$1500,"Quality",'1.PrepList'!$K$2:$K$1500,{"B/D","B","D"},'1.PrepList'!$B$2:$B$1500,"<>Yes")) -> 1 | AI4: =SUMPRODUCT(COUNTIFS('1.PrepList'!$L$2:$L$1500,"Quality",'1.PrepList'!$K$2:$K$1500,{"B/D","B","D"},'1.PrepList'!$O$2:$O$1500,"Passed",'1.PrepList'!$B$2:$B$1500,"<>Yes")) -> 1 | AJ4: =SUMPRODUCT(COUNTIFS('1.PrepList'!$L$2:$L$1500,"Test Operator",'1.PrepList'!$K$2:$K$1500,{"A/C","A","C"},'1.PrepList'!$B$2:$B$1500,"<>Yes")) -> 3 | AK4: =SUMPRODUCT(COUNTIFS('1.PrepList'!$L$2:$L$1500,"Test Operator",'1.PrepList'!$K$2:$K$1500,{"A/C","A","C"},'1.PrepList'!$O$2:$O$1500,"Passed",'1.PrepList'!$B$2:$B$1500,"<>Yes")) -> 1 | AL4: =SUMPRODUCT(COUNTIFS('1.PrepList'!$L$2:$L$1500,"Debug",'1.PrepList'!$K$2:$K$1500,{"A/C","A","C"},'1.PrepList'!$B$2:$B$1500,"<>Yes")) -> 0 | AM4: =SUMPRODUCT(COUNTIFS('1.PrepList'!$L$2:$L$1500,"Debug",'1.PrepList'!$K$2:$K$1500,{"A/C","A","C"},'1.PrepList'!$O$2:$O$1500,"Passed",'1.PrepList'!$B$2:$B$1500,"<>Yes")) -> 0 | AN4: =SUMPRODUCT(COUNTIFS('1.PrepList'!$L$2:$L$1500,"Debug Tech 4",'1.PrepList'!$K$2:$K$1500,{"B/D","B","D"},'1.PrepList'!$B$2:$B$1500,"<>Yes")) -> 0 | AO4: =SUMPRODUCT(COUNTIFS('1.PrepList'!$L$2:$L$1500,"Debug Tech 4",'1.PrepList'!$K$2:$K$1500,{"B/D","B","D"},'1.PrepList'!$O$2:$O$1500,"Passed",'1.PrepList'!$B$2:$B$1500,"<>Yes")) -> 0 | AP4: 2 | AQ4: 0 | AR4: 1 | AS4: 1 | AT4: 1 | AU4: 1 | AV4: 0 | AW4: 0 | AX4: 0 | AY4: 0 | AZ4: 0 | BA4: 0
A5: =Scorecard!$H$6 -> WJ | P5: Updated | Q5: 46197
A6: TOTAL | C6: =SUM(C2:C5) -> 0 | D6: =SUM(D2:D5) -> 0 | E6: =SUM(E2:E5) -> 0 | F6: =SUM(F2:F5) -> 0 | G6: =SUM(G2:G5) -> 0 | H6: =SUM(H2:H5) -> 0 | I6: =SUM(I2:I5) -> 0 | J6: =SUM(J2:J5) -> 0 | ... L6: =SUM(L2:L5) -> 0
P7: By Office
P8: Office | Q8: Prepped | R8: Cleared
A9: Date Last Posted | C9: WVC | D9: 45985 | E9: 45986 | F9: 45987 | G9: 45988 | H9: 45989 | K9: A Roster Starts | P9: NSL | Q9: =COUNTIFS('1.PrepList'!$I$2:$I$1500,"<>",'1.PrepList'!$B$2:$B$1500,"<>Yes",'1.PrepList'!$M$2:$M$1500,"NSL") -> 55 | R9: =COUNTIFS('1.PrepList'!$O$2:$O$1500,"Passed",'1.PrepList'!$B$2:$B$1500,"<>Yes",'1.PrepList'!$M$2:$M$1500,"NSL") -> 20
C10: QC Inspector - Days | D10: 5 | K10: B Roster Starts | P10: WVC | Q10: =COUNTIFS('1.PrepList'!$I$2:$I$1500,"<>",'1.PrepList'!$B$2:$B$1500,"<>Yes",'1.PrepList'!$M$2:$M$1500,"WVC") -> 75 | R10: =COUNTIFS('1.PrepList'!$O$2:$O$1500,"Passed",'1.PrepList'!$B$2:$B$1500,"<>Yes",'1.PrepList'!$M$2:$M$1500,"WVC") -> 29
C11: QC Inspector - Nights | D11: 0 | P11: WJ | Q11: =COUNTIFS('1.PrepList'!$I$2:$I$1500,"<>",'1.PrepList'!$B$2:$B$1500,"<>Yes",'1.PrepList'!$M$2:$M$1500,"WJ") -> 382 | R11: =COUNTIFS('1.PrepList'!$O$2:$O$1500,"Passed",'1.PrepList'!$B$2:$B$1500,"<>Yes",'1.PrepList'!$M$2:$M$1500,"WJ") -> 198
C12: 1st shift assembly | D12: 0
C13: 3rd shift assembly | D13: 0
A14: Date Last Posted | C14: WJ
C15: 3rd shift assembly | D15: 0
A18: Date Last Posted | C18: NSL
B19: Day - Warehouse | D19: 0
B20: Grave - Warehouse | D20: 0
B21: Grave - Quality Control | D21: 0
B22: Day - Quality Control | D22: 0
C24: Applies | D24: =SUM(D10:D23) -> 5 | E24: =SUM(E10:E23) -> 0 | F24: =SUM(F10:F23) -> 0 | G24: =SUM(G10:G23) -> 0 | H24: =SUM(H10:H23) -> 0 | I24: =SUM(I10:I23) -> 0 | J24: =SUM(J10:J23) -> 0
D25: by 5pm

Sheet Start Sheet For Flex
A1: Email must go out to the the addresses listed below: | B1: Example Email:
A2: alicia.velasquez@flex.com | H2: Date: | J2: New Starts
A3: Leah.Bergquist@flex.com | H3: Agency | I3: Req # | J3: Employee Name | K3: C# | L3: Shift | M3: Schedule | N3: Cost Center | O3: Job Title | P3: Supervisor | Q3: Shirt Size | R3: Start Date | S3: AD/Octa | T3: Checked In | U3: Comments
A4: us.slcbpsreception@flex.com | H4: YES | I4: =IF($K4="","",IFERROR(_xlfn.XLOOKUP($K4,_StartedStatus!$M:$M,_StartedStatus!$B:$B,"")&"","")) -> FLX0630 | J4: Jean Ramos Lopez | K4: C125977 | L4: C | M4: C Shift: Salt Lake City - O - 600am-600pm Rotating Sun,Mon,Thurs, Fri/Tues,Wed,Sat | N4: 1200 | O4: Production Specialist 1 - Dekit | P4: Jennifer Prudente (1168431) | Q4: M | R4: 46258.25 | S4: Yes | T4: FALSE
A5: katherine.tavera@flex.com | H5: YES | I5: =IF($K5="","",IFERROR(_xlfn.XLOOKUP($K5,_StartedStatus!$M:$M,_StartedStatus!$B:$B,"")&"","")) -> FLX0633 | J5: Urdaneta Miyelis | K5: C125978 | L5: C | M5: C Shift: Salt Lake City - O - 600am-600pm Rotating Sun,Mon,Thurs, Fri/Tues,Wed,Sat | N5: 1200 | O5: Production Specialist 1 - Dekit | P5: Jennifer Prudente (1168431) | Q5: =IF($K5="","",IFERROR(_xlfn.XLOOKUP($K5,_StartedStatus!$M:$M,_StartedStatus!$J:$J,"")&"","")) | R5: 46258.25 | S5: Yes | T5: FALSE
A6: howard.collings@flex.com | H6: YES | I6: =IF($K6="","",IFERROR(_xlfn.XLOOKUP($K6,_StartedStatus!$M:$M,_StartedStatus!$B:$B,"")&"","")) -> FLX0634 | J6: Ivan Chirinos | K6: C126095 | L6: C | M6: C Shift: Salt Lake City - O - 600am-600pm Rotating Sun,Mon,Thurs, Fri/Tues,Wed,Sat | N6: 1200 | O6: Production Specialist 1 - Dekit | P6: Jennifer Prudente (1168431) | Q6: M | R6: 46258.25 | S6: Yes | T6: FALSE
A7: us.slcsitehr@flex.com | H7: YES | I7: =IF($K7="","",IFERROR(_xlfn.XLOOKUP($K7,_StartedStatus!$M:$M,_StartedStatus!$B:$B,"")&"","")) -> FLX0635 | J7: Yisel Marquez | K7: C126096 | L7: C | M7: C Shift: Salt Lake City - O - 600am-600pm Rotating Sun,Mon,Thurs, Fri/Tues,Wed,Sat | N7: 1200 | O7: Production Specialist 1 - Dekit | P7: Jennifer Prudente (1168431) | Q7: M | R7: 46258.25 | S7: Yes | T7: FALSE
A8: us.slchrleads@flex.com | H8: YES | I8: =IF($K8="","",IFERROR(_xlfn.XLOOKUP($K8,_StartedStatus!$M:$M,_StartedStatus!$B:$B,"")&"","")) -> FLX0647 | J8: Dieneddys Navarro | K8: C125979 | L8: A | M8: A Shift: Salt Lake City - Q - 600am-600pm Rotating Tues,Wed,Sat/Sun,Mon, Thurs,Fri | N8: 1200 | O8: Production Specialist - L10 Repair (Bonepile) | P8: Jennifer Paz (1166697) | Q8: M | R8: 46258.25 | S8: Yes | T8: FALSE
A9: flex@youremploymentsolutions.com | H9: YES | I9: =IF($K9="","",IFERROR(_xlfn.XLOOKUP($K9,_StartedStatus!$M:$M,_StartedStatus!$B:$B,"")&"","")) -> FLX0656 | J9: Jenny Maria Arbelaez Pena | K9: C125980 | L9: B | M9: B Shift: Salt Lake City - P - 600pm-600a Rotating Tues,Wed,Sat/Sun,Mon,Thurs,Fri (15% Diff) | N9: 1200 | O9: Production Specialist - L10 Repair (Bonepile) | P9: Alexis Rullan | Q9: M | R9: 46258.25 | S9: Yes | T9: FALSE
A10: timothy.mcgovern@flex.com | H10: YES | I10: =IF($K10="","",IFERROR(_xlfn.XLOOKUP($K10,_StartedStatus!$M:$M,_StartedStatus!$B:$B,"")&"","")) | J10: Sandra Melendez | L10: D | M10: D Shift: Salt Lake City - N - 600pm-600a Rotating Sun,Mon,Thurs, Fri/Tues,Wed,Sat (15% Diff) | N10: 1200 | O10: Production Specialist - L10 Repair (Bonepile) | P10: Yalia Driggers (1153165) | Q10: M | R10: 46258.25 | S10: Yes | T10: FALSE
A11: Gil.Smith@flex.com | H11: YES | I11: =IF($K11="","",IFERROR(_xlfn.XLOOKUP($K11,_StartedStatus!$M:$M,_StartedStatus!$B:$B,"")&"","")) -> FLX0662 | J11: Walter Lesmes | K11: C125981 | L11: A | M11: A Shift: Salt Lake City - Q - 600am-600pm Rotating Tues,Wed,Sat/Sun,Mon, Thurs,Fri | N11: 1200 | O11: Production Specialist 1 - Mechanical Assembly | P11: Alondra Landin | Q11: L | R11: 46258.25 | S11: Yes | T11: FALSE
A12: Paulo.Gonzalez@flex.com | H12: YES | I12: =IF($K12="","",IFERROR(_xlfn.XLOOKUP($K12,_StartedStatus!$M:$M,_StartedStatus!$B:$B,"")&"","")) -> FLX0664 | J12: Kahirys Maria Melendez | K12: C125982 | L12: A | M12: A Shift: Salt Lake City - Q - 600am-600pm Rotating Tues,Wed,Sat/Sun,Mon, Thurs,Fri | N12: 1200 | O12: Production Specialist 1 - Mechanical Assembly | P12: Jose Gonzalez | Q12: M | R12: 46258.25 | S12: Yes | T12: FALSE
A13: Christopher.Villanueva@flex.com | H13: YES | I13: =IF($K13="","",IFERROR(_xlfn.XLOOKUP($K13,_StartedStatus!$M:$M,_StartedStatus!$B:$B,"")&"","")) -> FLX0671 | J13: Juan Pablo Saenz | K13: C125983 | L13: C | M13: C Shift: Salt Lake City - O - 600am-600pm Rotating Sun,Mon,Thurs, Fri/Tues,Wed,Sat | N13: 1200 | O13: Production Specialist 1 - Cold Room | P13: Yaritza Garza | Q13: =IF($K13="","",IFERROR(_xlfn.XLOOKUP($K13,_StartedStatus!$M:$M,_StartedStatus!$J:$J,"")&"","")) | R13: 46258.25 | S13: Yes | T13: FALSE
A14: Edwin.Paballa@flex.com | H14: YES | I14: =IF($K14="","",IFERROR(_xlfn.XLOOKUP($K14,_StartedStatus!$M:$M,_StartedStatus!$B:$B,"")&"","")) -> FLX0679 | J14: Nelly Parra Lucena | K14: C126002 | L14: A | M14: A Shift: Salt Lake City - Q - 600am-600pm Rotating Tues,Wed,Sat/Sun,Mon, Thurs,Fri | N14: 1200 | O14: Production Specialist 1 - Mechanical Assembly | P14: Alondra Landin | Q14: =IF($K14="","",IFERROR(_xlfn.XLOOKUP($K14,_StartedStatus!$M:$M,_StartedStatus!$J:$J,"")&"","")) | R14: 46258.25 | S14: Yes | T14: FALSE
A15: Avigail.Zamora@flex.com | H15: YES | I15: =IF($K15="","",IFERROR(_xlfn.XLOOKUP($K15,_StartedStatus!$M:$M,_StartedStatus!$B:$B,"")&"","")) -> FLX0680 | J15: Ghileny Garces Parra | K15: C126009 | L15: A | M15: A Shift: Salt Lake City - Q - 600am-600pm Rotating Tues,Wed,Sat/Sun,Mon, Thurs,Fri | N15: 1200 | O15: Production Specialist 1 - Mechanical Assembly | P15: Alondra Landin | Q15: =IF($K15="","",IFERROR(_xlfn.XLOOKUP($K15,_StartedStatus!$M:$M,_StartedStatus!$J:$J,"")&"","")) | R15: 46258.25 | S15: Yes | T15: FALSE
A16: Us.slctrainingteam@flex.com | H16: YES | I16: =IF($K16="","",IFERROR(_xlfn.XLOOKUP($K16,_StartedStatus!$M:$M,_StartedStatus!$B:$B,"")&"","")) -> FLX0681 | J16: Loinny Avila | K16: C126025 | L16: A | M16: A Shift: Salt Lake City - Q - 600am-600pm Rotating Tues,Wed,Sat/Sun,Mon, Thurs,Fri | N16: 1200 | O16: Production Specialist 1 - Cold Room | P16: Barbara Garcia (1137177) | Q16: =IF($K16="","",IFERROR(_xlfn.XLOOKUP($K16,_StartedStatus!$M:$M,_StartedStatus!$J:$J,"")&"","")) | R16: 46258.25 | S16: Yes | T16: FALSE
A17: Jennifer.Medina@flex.com | H17: YES | I17: =IF($K17="","",IFERROR(_xlfn.XLOOKUP($K17,_StartedStatus!$M:$M,_StartedStatus!$B:$B,"")&"","")) -> FLX0687 | J17: Miguel Penuela Sequera | K17: C126015 | L17: C | M17: C Shift: Salt Lake City - O - 600am-600pm Rotating Sun,Mon,Thurs, Fri/Tues,Wed,Sat | N17: 1200 | O17: Production Specialist 1 - Materials | P17: Mariana Ballesteros (1174672) | Q17: =IF($K17="","",IFERROR(_xlfn.XLOOKUP($K17,_StartedStatus!$M:$M,_StartedStatus!$J:$J,"")&"","")) | R17: 46258.25 | S17: Yes | T17: FALSE
H18: YES | I18: =IF($K18="","",IFERROR(_xlfn.XLOOKUP($K18,_StartedStatus!$M:$M,_StartedStatus!$B:$B,"")&"","")) -> FLX0688 | J18: Stefani Rios | K18: C126018 | L18: C | M18: C Shift: Salt Lake City - O - 600am-600pm Rotating Sun,Mon,Thurs, Fri/Tues,Wed,Sat | N18: 1200 | O18: Production Specialist 1 - Materials | P18: Mariana Ballesteros (1174672) | Q18: =IF($K18="","",IFERROR(_xlfn.XLOOKUP($K18,_StartedStatus!$M:$M,_StartedStatus!$J:$J,"")&"","")) | R18: 46258.25 | S18: Yes | T18: FALSE
H19: YES | I19: =IF($K19="","",IFERROR(_xlfn.XLOOKUP($K19,_StartedStatus!$M:$M,_StartedStatus!$B:$B,"")&"","")) -> FLX0690 | J19: Ricardo Merril | K19: C126023 | L19: C | M19: C Shift: Salt Lake City - O - 600am-600pm Rotating Sun,Mon,Thurs, Fri/Tues,Wed,Sat | N19: 1200 | O19: Production Specialist 1 - Materials | P19: Dario Mendez Toyo (1174155) | Q19: =IF($K19="","",IFERROR(_xlfn.XLOOKUP($K19,_StartedStatus!$M:$M,_StartedStatus!$J:$J,"")&"","")) | R19: 46258.25 | S19: Yes | T19: FALSE
H20: YES | I20: =IF($K20="","",IFERROR(_xlfn.XLOOKUP($K20,_StartedStatus!$M:$M,_StartedStatus!$B:$B,"")&"","")) -> FLX0691 | J20: Maria Cruz | K20: C126021 | L20: C | M20: C Shift: Salt Lake City - O - 600am-600pm Rotating Sun,Mon,Thurs, Fri/Tues,Wed,Sat | N20: 1200 | O20: Production Specialist 1 - Mechanical Assembly | P20: Valeria Mendez (1181800) | Q20: =IF($K20="","",IFERROR(_xlfn.XLOOKUP($K20,_StartedStatus!$M:$M,_StartedStatus!$J:$J,"")&"","")) | R20: 46258.25 | S20: Yes | T20: FALSE
H21: YES | I21: =IF($K21="","",IFERROR(_xlfn.XLOOKUP($K21,_StartedStatus!$M:$M,_StartedStatus!$B:$B,"")&"","")) -> FLX0700 | J21: Jorge Aldana | K21: C126044 | L21: B | M21: B Shift: Salt Lake City - P - 600pm-600a Rotating Tues,Wed,Sat/Sun,Mon,Thurs,Fri (15% Diff) | N21: 1200 | O21: Production Specialist 1 - Materials | P21: Sanel Kudic | Q21: =IF($K21="","",IFERROR(_xlfn.XLOOKUP($K21,_StartedStatus!$M:$M,_StartedStatus!$J:$J,"")&"","")) | R21: 46258.25 | S21: Yes | T21: FALSE
H22: YES | I22: =IF($K22="","",IFERROR(_xlfn.XLOOKUP($K22,_StartedStatus!$M:$M,_StartedStatus!$B:$B,"")&"","")) -> FLX0702 | J22: Elias Dobieksi | K22: C126045 | L22: B | M22: B Shift: Salt Lake City - P - 600pm-600a Rotating Tues,Wed,Sat/Sun,Mon,Thurs,Fri (15% Diff) | N22: 1200 | O22: Production Specialist 1 - Materials | P22: Paola Guzman | Q22: =IF($K22="","",IFERROR(_xlfn.XLOOKUP($K22,_StartedStatus!$M:$M,_StartedStatus!$J:$J,"")&"","")) | R22: 46258.25 | S22: Yes | T22: FALSE
H23: YES | I23: =IF($K23="","",IFERROR(_xlfn.XLOOKUP($K23,_StartedStatus!$M:$M,_StartedStatus!$B:$B,"")&"","")) -> FLX0703 | J23: Pedro Ruis Medina | K23: C126014 | L23: B | M23: B Shift: Salt Lake City - P - 600pm-600a Rotating Tues,Wed,Sat/Sun,Mon,Thurs,Fri (15% Diff) | N23: 1200 | O23: Production Specialist 1 - Materials | P23: Paola Guzman | Q23: M | R23: 46258.25 | S23: Yes | T23: FALSE
H24: YES | I24: =IF($K24="","",IFERROR(_xlfn.XLOOKUP($K24,_StartedStatus!$M:$M,_StartedStatus!$B:$B,"")&"","")) -> FLX0711 | J24: Gabriel Alviarez | K24: C126013 | L24: D | M24: D Shift: Salt Lake City - N - 600pm-600a Rotating Sun,Mon,Thurs, Fri/Tues,Wed,Sat (15% Diff) | N24: 1200 | O24: Production Specialist 1 - Materials | P24: Gaige Snow | Q24: =IF($K24="","",IFERROR(_xlfn.XLOOKUP($K24,_StartedStatus!$M:$M,_StartedStatus!$J:$J,"")&"","")) | R24: 46258.25 | S24: Yes | T24: FALSE
H25: YES | I25: =IF($K25="","",IFERROR(_xlfn.XLOOKUP($K25,_StartedStatus!$M:$M,_StartedStatus!$B:$B,"")&"","")) -> FLX0712 | J25: Yorman Yanez | K25: C126012 | L25: D | M25: D Shift: Salt Lake City - N - 600pm-600a Rotating Sun,Mon,Thurs, Fri/Tues,Wed,Sat (15% Diff) | N25: 1200 | O25: Production Specialist 1 - Materials | P25: Gaige Snow | Q25: M | R25: 46258.25 | S25: Yes | T25: FALSE
H26: YES | I26: =IF($K26="","",IFERROR(_xlfn.XLOOKUP($K26,_StartedStatus!$M:$M,_StartedStatus!$B:$B,"")&"","")) -> FLX0714 | J26: Kimberly Martinez | K26: C126010 | L26: D | M26: D Shift: Salt Lake City - N - 600pm-600a Rotating Sun,Mon,Thurs, Fri/Tues,Wed,Sat (15% Diff) | N26: 1200 | O26: Production Specialist 1 - Materials | P26: Mel Kellar (1142020) | Q26: M | R26: 46258.25 | S26: Yes | T26: FALSE
H27: =IF($K27="","","YES") -> YES | I27: =IF($K27="","",IFERROR(_xlfn.XLOOKUP($K27,_StartedStatus!$M:$M,_StartedStatus!$B:$B,"")&"","")) -> FLX0711 | J27: =IF($K27="","",IFERROR(_xlfn.XLOOKUP($K27,_StartedStatus!$M:$M,_StartedStatus!$F:$F,"")&"","")) -> Gabriel Alviarez | K27: C126013 | L27: =IF($M27="","",LEFT(TRIM($M27),1)) -> D | M27: =IF($K27="","",IFERROR(_xlfn.XLOOKUP($K27,_StartedStatus!$M:$M,_StartedStatus!$L:$L,"")&"","")) -> D Shift: Salt Lake City - N - 600pm-600a Rotating Sun,Mon,Thurs, Fri/Tues,Wed,Sat (15% Diff) | N27: =IF($K27="","",1200) -> 1200 | O27: =IF($K27="","",IFERROR(_xlfn.XLOOKUP($K27,_StartedStatus!$M:$M,_StartedStatus!$K:$K,"")&"","")) -> Production Specialist 1 - Materials | P27: =IF($K27="","",IFERROR(_xlfn.XLOOKUP($K27,_StartedStatus!$M:$M,_StartedStatus!$C:$C,"")&"","")) -> Gaige Snow | Q27: =IF($K27="","",IFERROR(_xlfn.XLOOKUP($K27,_StartedStatus!$M:$M,_StartedStatus!$J:$J,"")&"","")) | R27: =IF($K27="","",IFERROR(_xlfn.XLOOKUP($K27,_StartedStatus!$M:$M,_StartedStatus!$U:$U,""),"")) -> 0 | S27: =IF($K27="","","Yes") -> Yes | T27: FALSE
H28: =IF($K28="","","YES") -> YES | I28: =IF($K28="","",IFERROR(_xlfn.XLOOKUP($K28,_StartedStatus!$M:$M,_StartedStatus!$B:$B,"")&"","")) -> FLX0712 | J28: =IF($K28="","",IFERROR(_xlfn.XLOOKUP($K28,_StartedStatus!$M:$M,_StartedStatus!$F:$F,"")&"","")) -> Yorman Yanez | K28: C126012 | L28: =IF($M28="","",LEFT(TRIM($M28),1)) -> D | M28: =IF($K28="","",IFERROR(_xlfn.XLOOKUP($K28,_StartedStatus!$M:$M,_StartedStatus!$L:$L,"")&"","")) -> D Shift: Salt Lake City - N - 600pm-600a Rotating Sun,Mon,Thurs, Fri/Tues,Wed,Sat (15% Diff) | N28: =IF($K28="","",1200) -> 1200 | O28: =IF($K28="","",IFERROR(_xlfn.XLOOKUP($K28,_StartedStatus!$M:$M,_StartedStatus!$K:$K,"")&"","")) -> Production Specialist 1 - Materials | P28: =IF($K28="","",IFERROR(_xlfn.XLOOKUP($K28,_StartedStatus!$M:$M,_StartedStatus!$C:$C,"")&"","")) -> Gaige Snow | Q28: =IF($K28="","",IFERROR(_xlfn.XLOOKUP($K28,_StartedStatus!$M:$M,_StartedStatus!$J:$J,"")&"","")) -> M | R28: =IF($K28="","",IFERROR(_xlfn.XLOOKUP($K28,_StartedStatus!$M:$M,_StartedStatus!$U:$U,""),"")) -> 0 | S28: =IF($K28="","","Yes") -> Yes | T28: FALSE
H29: =IF($K29="","","YES") -> YES | I29: =IF($K29="","",IFERROR(_xlfn.XLOOKUP($K29,_StartedStatus!$M:$M,_StartedStatus!$B:$B,"")&"","")) -> FLX0714 | J29: =IF($K29="","",IFERROR(_xlfn.XLOOKUP($K29,_StartedStatus!$M:$M,_StartedStatus!$F:$F,"")&"","")) -> Kimberly Martinez | K29: C126010 | L29: =IF($M29="","",LEFT(TRIM($M29),1)) -> D | M29: =IF($K29="","",IFERROR(_xlfn.XLOOKUP($K29,_StartedStatus!$M:$M,_StartedStatus!$L:$L,"")&"","")) -> D Shift: Salt Lake City - N - 600pm-600a Rotating Sun,Mon,Thurs, Fri/Tues,Wed,Sat (15% Diff) | N29: =IF($K29="","",1200) -> 1200 | O29: =IF($K29="","",IFERROR(_xlfn.XLOOKUP($K29,_StartedStatus!$M:$M,_StartedStatus!$K:$K,"")&"","")) -> Production Specialist 1 - Materials | P29: =IF($K29="","",IFERROR(_xlfn.XLOOKUP($K29,_StartedStatus!$M:$M,_StartedStatus!$C:$C,"")&"","")) -> Mel Kellar (1142020) | Q29: =IF($K29="","",IFERROR(_xlfn.XLOOKUP($K29,_StartedStatus!$M:$M,_StartedStatus!$J:$J,"")&"","")) -> M | R29: =IF($K29="","",IFERROR(_xlfn.XLOOKUP($K29,_StartedStatus!$M:$M,_StartedStatus!$U:$U,""),"")) -> 0 | S29: =IF($K29="","","Yes") -> Yes | T29: FALSE
H30: =IF($K30="","","YES") | I30: =IF($K30="","",IFERROR(_xlfn.XLOOKUP($K30,_StartedStatus!$M:$M,_StartedStatus!$B:$B,"")&"","")) | J30: =IF($K30="","",IFERROR(_xlfn.XLOOKUP($K30,_StartedStatus!$M:$M,_StartedStatus!$F:$F,"")&"","")) | L30: =IF($M30="","",LEFT(TRIM($M30),1)) | M30: =IF($K30="","",IFERROR(_xlfn.XLOOKUP($K30,_StartedStatus!$M:$M,_StartedStatus!$L:$L,"")&"","")) | N30: =IF($K30="","",1200) | O30: =IF($K30="","",IFERROR(_xlfn.XLOOKUP($K30,_StartedStatus!$M:$M,_StartedStatus!$K:$K,"")&"","")) | P30: =IF($K30="","",IFERROR(_xlfn.XLOOKUP($K30,_StartedStatus!$M:$M,_StartedStatus!$C:$C,"")&"","")) | Q30: =IF($K30="","",IFERROR(_xlfn.XLOOKUP($K30,_StartedStatus!$M:$M,_StartedStatus!$J:$J,"")&"","")) | R30: =IF($K30="","",IFERROR(_xlfn.XLOOKUP($K30,_StartedStatus!$M:$M,_StartedStatus!$U:$U,""),"")) | S30: =IF($K30="","","Yes") | T30: FALSE
H31: =IF($K31="","","YES") | I31: =IF($K31="","",IFERROR(_xlfn.XLOOKUP($K31,_StartedStatus!$M:$M,_StartedStatus!$B:$B,"")&"","")) | J31: =IF($K31="","",IFERROR(_xlfn.XLOOKUP($K31,_StartedStatus!$M:$M,_StartedStatus!$F:$F,"")&"","")) | L31: =IF($M31="","",LEFT(TRIM($M31),1)) | M31: =IF($K31="","",IFERROR(_xlfn.XLOOKUP($K31,_StartedStatus!$M:$M,_StartedStatus!$L:$L,"")&"","")) | N31: =IF($K31="","",1200) | O31: =IF($K31="","",IFERROR(_xlfn.XLOOKUP($K31,_StartedStatus!$M:$M,_StartedStatus!$K:$K,"")&"","")) | P31: =IF($K31="","",IFERROR(_xlfn.XLOOKUP($K31,_StartedStatus!$M:$M,_StartedStatus!$C:$C,"")&"","")) | Q31: =IF($K31="","",IFERROR(_xlfn.XLOOKUP($K31,_StartedStatus!$M:$M,_StartedStatus!$J:$J,"")&"","")) | R31: =IF($K31="","",IFERROR(_xlfn.XLOOKUP($K31,_StartedStatus!$M:$M,_StartedStatus!$U:$U,""),"")) | S31: =IF($K31="","","Yes") | T31: FALSE
H32: =IF($K32="","","YES") | I32: =IF($K32="","",IFERROR(_xlfn.XLOOKUP($K32,_StartedStatus!$M:$M,_StartedStatus!$B:$B,"")&"","")) | J32: =IF($K32="","",IFERROR(_xlfn.XLOOKUP($K32,_StartedStatus!$M:$M,_StartedStatus!$F:$F,"")&"","")) | L32: =IF($M32="","",LEFT(TRIM($M32),1)) | M32: =IF($K32="","",IFERROR(_xlfn.XLOOKUP($K32,_StartedStatus!$M:$M,_StartedStatus!$L:$L,"")&"","")) | N32: =IF($K32="","",1200) | O32: =IF($K32="","",IFERROR(_xlfn.XLOOKUP($K32,_StartedStatus!$M:$M,_StartedStatus!$K:$K,"")&"","")) | P32: =IF($K32="","",IFERROR(_xlfn.XLOOKUP($K32,_StartedStatus!$M:$M,_StartedStatus!$C:$C,"")&"","")) | Q32: =IF($K32="","",IFERROR(_xlfn.XLOOKUP($K32,_StartedStatus!$M:$M,_StartedStatus!$J:$J,"")&"","")) | R32: =IF($K32="","",IFERROR(_xlfn.XLOOKUP($K32,_StartedStatus!$M:$M,_StartedStatus!$U:$U,""),"")) | S32: =IF($K32="","","Yes") | T32: FALSE
H33: =IF($K33="","","YES") | I33: =IF($K33="","",IFERROR(_xlfn.XLOOKUP($K33,_StartedStatus!$M:$M,_StartedStatus!$B:$B,"")&"","")) | J33: =IF($K33="","",IFERROR(_xlfn.XLOOKUP($K33,_StartedStatus!$M:$M,_StartedStatus!$F:$F,"")&"","")) | L33: =IF($M33="","",LEFT(TRIM($M33),1)) | M33: =IF($K33="","",IFERROR(_xlfn.XLOOKUP($K33,_StartedStatus!$M:$M,_StartedStatus!$L:$L,"")&"","")) | N33: =IF($K33="","",1200) | O33: =IF($K33="","",IFERROR(_xlfn.XLOOKUP($K33,_StartedStatus!$M:$M,_StartedStatus!$K:$K,"")&"","")) | P33: =IF($K33="","",IFERROR(_xlfn.XLOOKUP($K33,_StartedStatus!$M:$M,_StartedStatus!$C:$C,"")&"","")) | Q33: =IF($K33="","",IFERROR(_xlfn.XLOOKUP($K33,_StartedStatus!$M:$M,_StartedStatus!$J:$J,"")&"","")) | R33: =IF($K33="","",IFERROR(_xlfn.XLOOKUP($K33,_StartedStatus!$M:$M,_StartedStatus!$U:$U,""),"")) | S33: =IF($K33="","","Yes") | T33: FALSE
H34: =IF($K34="","","YES") | I34: =IF($K34="","",IFERROR(_xlfn.XLOOKUP($K34,_StartedStatus!$M:$M,_StartedStatus!$B:$B,"")&"","")) | J34: =IF($K34="","",IFERROR(_xlfn.XLOOKUP($K34,_StartedStatus!$M:$M,_StartedStatus!$F:$F,"")&"","")) | L34: =IF($M34="","",LEFT(TRIM($M34),1)) | M34: =IF($K34="","",IFERROR(_xlfn.XLOOKUP($K34,_StartedStatus!$M:$M,_StartedStatus!$L:$L,"")&"","")) | N34: =IF($K34="","",1200) | O34: =IF($K34="","",IFERROR(_xlfn.XLOOKUP($K34,_StartedStatus!$M:$M,_StartedStatus!$K:$K,"")&"","")) | P34: =IF($K34="","",IFERROR(_xlfn.XLOOKUP($K34,_StartedStatus!$M:$M,_StartedStatus!$C:$C,"")&"","")) | Q34: =IF($K34="","",IFERROR(_xlfn.XLOOKUP($K34,_StartedStatus!$M:$M,_StartedStatus!$J:$J,"")&"","")) | R34: =IF($K34="","",IFERROR(_xlfn.XLOOKUP($K34,_StartedStatus!$M:$M,_StartedStatus!$U:$U,""),"")) | S34: =IF($K34="","","Yes") | T34: FALSE
H35: =IF($K35="","","YES") | I35: =IF($K35="","",IFERROR(_xlfn.XLOOKUP($K35,_StartedStatus!$M:$M,_StartedStatus!$B:$B,"")&"","")) | J35: =IF($K35="","",IFERROR(_xlfn.XLOOKUP($K35,_StartedStatus!$M:$M,_StartedStatus!$F:$F,"")&"","")) | L35: =IF($M35="","",LEFT(TRIM($M35),1)) | M35: =IF($K35="","",IFERROR(_xlfn.XLOOKUP($K35,_StartedStatus!$M:$M,_StartedStatus!$L:$L,"")&"","")) | N35: =IF($K35="","",1200) | O35: =IF($K35="","",IFERROR(_xlfn.XLOOKUP($K35,_StartedStatus!$M:$M,_StartedStatus!$K:$K,"")&"","")) | P35: =IF($K35="","",IFERROR(_xlfn.XLOOKUP($K35,_StartedStatus!$M:$M,_StartedStatus!$C:$C,"")&"","")) | Q35: =IF($K35="","",IFERROR(_xlfn.XLOOKUP($K35,_StartedStatus!$M:$M,_StartedStatus!$J:$J,"")&"","")) | R35: =IF($K35="","",IFERROR(_xlfn.XLOOKUP($K35,_StartedStatus!$M:$M,_StartedStatus!$U:$U,""),"")) | S35: =IF($K35="","","Yes") | T35: FALSE
H36: =IF($K36="","","YES") | I36: =IF($K36="","",IFERROR(_xlfn.XLOOKUP($K36,_StartedStatus!$M:$M,_StartedStatus!$B:$B,"")&"","")) | J36: =IF($K36="","",IFERROR(_xlfn.XLOOKUP($K36,_StartedStatus!$M:$M,_StartedStatus!$F:$F,"")&"","")) | L36: =IF($M36="","",LEFT(TRIM($M36),1)) | M36: =IF($K36="","",IFERROR(_xlfn.XLOOKUP($K36,_StartedStatus!$M:$M,_StartedStatus!$L:$L,"")&"","")) | N36: =IF($K36="","",1200) | O36: =IF($K36="","",IFERROR(_xlfn.XLOOKUP($K36,_StartedStatus!$M:$M,_StartedStatus!$K:$K,"")&"","")) | P36: =IF($K36="","",IFERROR(_xlfn.XLOOKUP($K36,_StartedStatus!$M:$M,_StartedStatus!$C:$C,"")&"","")) | Q36: =IF($K36="","",IFERROR(_xlfn.XLOOKUP($K36,_StartedStatus!$M:$M,_StartedStatus!$J:$J,"")&"","")) | R36: =IF($K36="","",IFERROR(_xlfn.XLOOKUP($K36,_StartedStatus!$M:$M,_StartedStatus!$U:$U,""),"")) | S36: =IF($K36="","","Yes") | T36: FALSE
H37: =IF($K37="","","YES") | I37: =IF($K37="","",IFERROR(_xlfn.XLOOKUP($K37,_StartedStatus!$M:$M,_StartedStatus!$B:$B,"")&"","")) | J37: =IF($K37="","",IFERROR(_xlfn.XLOOKUP($K37,_StartedStatus!$M:$M,_StartedStatus!$F:$F,"")&"","")) | L37: =IF($M37="","",LEFT(TRIM($M37),1)) | M37: =IF($K37="","",IFERROR(_xlfn.XLOOKUP($K37,_StartedStatus!$M:$M,_StartedStatus!$L:$L,"")&"","")) | N37: =IF($K37="","",1200) | O37: =IF($K37="","",IFERROR(_xlfn.XLOOKUP($K37,_StartedStatus!$M:$M,_StartedStatus!$K:$K,"")&"","")) | P37: =IF($K37="","",IFERROR(_xlfn.XLOOKUP($K37,_StartedStatus!$M:$M,_StartedStatus!$C:$C,"")&"","")) | Q37: =IF($K37="","",IFERROR(_xlfn.XLOOKUP($K37,_StartedStatus!$M:$M,_StartedStatus!$J:$J,"")&"","")) | R37: =IF($K37="","",IFERROR(_xlfn.XLOOKUP($K37,_StartedStatus!$M:$M,_StartedStatus!$U:$U,""),"")) | S37: =IF($K37="","","Yes") | T37: FALSE
H38: =IF($K38="","","YES") | I38: =IF($K38="","",IFERROR(_xlfn.XLOOKUP($K38,_StartedStatus!$M:$M,_StartedStatus!$B:$B,"")&"","")) | J38: =IF($K38="","",IFERROR(_xlfn.XLOOKUP($K38,_StartedStatus!$M:$M,_StartedStatus!$F:$F,"")&"","")) | L38: =IF($M38="","",LEFT(TRIM($M38),1)) | M38: =IF($K38="","",IFERROR(_xlfn.XLOOKUP($K38,_StartedStatus!$M:$M,_StartedStatus!$L:$L,"")&"","")) | N38: =IF($K38="","",1200) | O38: =IF($K38="","",IFERROR(_xlfn.XLOOKUP($K38,_StartedStatus!$M:$M,_StartedStatus!$K:$K,"")&"","")) | P38: =IF($K38="","",IFERROR(_xlfn.XLOOKUP($K38,_StartedStatus!$M:$M,_StartedStatus!$C:$C,"")&"","")) | Q38: =IF($K38="","",IFERROR(_xlfn.XLOOKUP($K38,_StartedStatus!$M:$M,_StartedStatus!$J:$J,"")&"","")) | R38: =IF($K38="","",IFERROR(_xlfn.XLOOKUP($K38,_StartedStatus!$M:$M,_StartedStatus!$U:$U,""),"")) | S38: =IF($K38="","","Yes") | T38: FALSE
H39: =IF($K39="","","YES") | I39: =IF($K39="","",IFERROR(_xlfn.XLOOKUP($K39,_StartedStatus!$M:$M,_StartedStatus!$B:$B,"")&"","")) | J39: =IF($K39="","",IFERROR(_xlfn.XLOOKUP($K39,_StartedStatus!$M:$M,_StartedStatus!$F:$F,"")&"","")) | L39: =IF($M39="","",LEFT(TRIM($M39),1)) | M39: =IF($K39="","",IFERROR(_xlfn.XLOOKUP($K39,_StartedStatus!$M:$M,_StartedStatus!$L:$L,"")&"","")) | N39: =IF($K39="","",1200) | O39: =IF($K39="","",IFERROR(_xlfn.XLOOKUP($K39,_StartedStatus!$M:$M,_StartedStatus!$K:$K,"")&"","")) | P39: =IF($K39="","",IFERROR(_xlfn.XLOOKUP($K39,_StartedStatus!$M:$M,_StartedStatus!$C:$C,"")&"","")) | Q39: =IF($K39="","",IFERROR(_xlfn.XLOOKUP($K39,_StartedStatus!$M:$M,_StartedStatus!$J:$J,"")&"","")) | R39: =IF($K39="","",IFERROR(_xlfn.XLOOKUP($K39,_StartedStatus!$M:$M,_StartedStatus!$U:$U,""),"")) | S39: =IF($K39="","","Yes") | T39: FALSE
H40: =IF($K40="","","YES") | I40: =IF($K40="","",IFERROR(_xlfn.XLOOKUP($K40,_StartedStatus!$M:$M,_StartedStatus!$B:$B,"")&"","")) | J40: =IF($K40="","",IFERROR(_xlfn.XLOOKUP($K40,_StartedStatus!$M:$M,_StartedStatus!$F:$F,"")&"","")) | L40: =IF($M40="","",LEFT(TRIM($M40),1)) | M40: =IF($K40="","",IFERROR(_xlfn.XLOOKUP($K40,_StartedStatus!$M:$M,_StartedStatus!$L:$L,"")&"","")) | N40: =IF($K40="","",1200) | O40: =IF($K40="","",IFERROR(_xlfn.XLOOKUP($K40,_StartedStatus!$M:$M,_StartedStatus!$K:$K,"")&"","")) | P40: =IF($K40="","",IFERROR(_xlfn.XLOOKUP($K40,_StartedStatus!$M:$M,_StartedStatus!$C:$C,"")&"","")) | Q40: =IF($K40="","",IFERROR(_xlfn.XLOOKUP($K40,_StartedStatus!$M:$M,_StartedStatus!$J:$J,"")&"","")) | R40: =IF($K40="","",IFERROR(_xlfn.XLOOKUP($K40,_StartedStatus!$M:$M,_StartedStatus!$U:$U,""),"")) | S40: =IF($K40="","","Yes") | T40: FALSE
...

Sheet Hired
A1: Date | B1: Last Contacted | C1: Status | D1: Language | E1: Employee Name (must match Avionte) | F1: Talent ID | G1: Phone | H1: Shift Preference | I1: Position | J1: Office | K1: Recruiter | L1: BG? | M1: DT? | N1: FLEX Doc Sent | O1: Attended Mini Orientation | P1: Notes
A2: 46128 | D2: Spanish | E2: Joanna Munoz | F2: 216559414 | G2: 3854439875 | H2: Night Shift | I2: Mechanical Assembly | J2: WVC | K2: JY | L2: Passed | M2: Passed | N2: Passed | O2: Yes
A3: 46125 | D3: Spanish | E3: Laura Ambriz | F3: 96619838 | G3: 3853370012 | H3: Day Shift | I3: Mechanical Assembly | J3: WVC | K3: JY | L3: Passed | M3: Passed | N3: Passed
A4: 46125 | D4: Spanish | E4: Hildemaro Vargas | F4: 221840574 | G4: 3854050571 | H4: Night Shift | I4: Mechanical Assembly | J4: WJ | K4: NM | L4: Pending | M4: Passed | N4: Passed | O4: Yes
A5: 46122 | D5: Spanish | E5: Desiree Roa | F5: 199708572 | G5: 3854363656 | H5: Night Shift | I5: Mechanical Assembly | J5: WVC | K5: JY | L5: Pending | M5: Passed | N5: Passed | O5: Yes
A6: 46112 | D6: Bilingual | E6: Alondra Portillo | F6: 134090007 | G6: 801 205-1714 | H6: Night Shift | I6: Mechanical Assembly | J6: WJ | K6: NM | L6: Passed | M6: Passed | N6: Passed | O6: Yes
A7: 46112 | D7: Spanish | E7: Franklin Marroquin | F7: 221153634 | G7: 8016697856 | H7: Night Shift | I7: Mechanical Assembly | J7: WJ | K7: NM | L7: Passed | M7: Passed | N7: Passed | O7: Yes
A8: 46112 | D8: Spanish | E8: Lina Mendoza Mantilla | F8: 129270240 | G8: 7153106810 | H8: Night Shift | I8: Mechanical Assembly | J8: WVC | K8: HB | L8: Pending | M8: Passed | N8: Passed
A9: 46111 | D9: Spanish | E9: Orlando Herrera | F9: 146893715 | G9: 3854143049 | H9: Night Shift | I9: Mechanical Assembly | J9: WJ | K9: NM | L9: Pending | M9: Passed | N9: Passed | O9: Yes
A10: 46105 | D10: Spanish | E10: Cesar Paredes | F10: 220962745 | G10: (385) 445-0455 | H10: Night Shift | I10: Mechanical Assembly | J10: WJ | K10: NM | L10: Passed | M10: Passed | N10: Passed | O10: Yes
A11: 46022 | D11: Spanish | E11: Maira Colmenarez | F11: 182102784 | G11: 8529853652 | H11: Night Shift | I11: Mechanical Assembly | J11: WJ | K11: NM | L11: Passed | M11: Passed | N11: Passed | O11: Yes
A12: 46097 | D12: Spanish | E12: Robinson Portillo | F12: 220528859 | G12: 3855036486 | H12: Night Shift | I12: Mechanical Assembly | J12: WJ | K12: NM | L12: Pending | M12: Passed | N12: Passed | O12: Yes
A13: 46091 | D13: Spanish | E13: Eric Ahumada | F13: 219148124 | G13: 4359383183 | H13: Day Shift | I13: Mechanical Assembly | J13: WJ | K13: NM | L13: Pending | M13: Passed | N13: Passed
A14: 46090 | D14: Spanish | E14: Karla Saras | F14: 194460546 | G14: 8019008532 | H14: Night Shift | I14: Mechanical Assembly | J14: WJ | K14: NM | L14: Passed | M14: Passed | N14: Passed | O14: Yes
A15: 46085 | D15: Spanish | E15: Glencis Pacheco | F15: 219091840 | G15: 3853790835 | H15: Day Shift | I15: Mechanical Assembly | J15: WJ | K15: NM | L15: Pending | M15: Passed | N15: Passed | O15: Yes
A16: 46084 | D16: Spanish | E16: Aurora Lamas Arellano | F16: 219012962 | G16: 3852965337 | H16: Day Shift | I16: Mechanical Assembly | J16: WJ | K16: FZ | L16: Pending | M16: Passed | N16: Passed
A17: 46083 | D17: Spanish | E17: Jorge Villarreal | F17: 218763933 | G17: 8013016176 | H17: Night Shift | I17: Mechanical Assembly | J17: WJ | K17: NM | L17: Pending | M17: Passed | N17: Passed | O17: Yes
A18: 46080 | D18: Bilingual | E18: Dulce Lopez | F18: 198189443 | G18: 3852950100 | H18: Day Shift | I18: Mechanical Assembly | J18: WVC | K18: JY | L18: Passed | M18: Passed | N18: Passed | O18: Pending
A19: 46080 | D19: Spanish | E19: Yoselin Castillo | F19: 164911604 | G19: 8013853512 | H19: Day Shift | I19: Mechanical Assembly | J19: WJ | K19: BL | L19: Passed | M19: Passed | N19: Passed
A20: 46078 | D20: Spanish | E20: Roderlys Quiche | F20: 218825186 | G20: 8013810242 | H20: Night Shift | I20: Mechanical Assembly | J20: WJ | K20: BL | L20: Passed | M20: Passed | N20: Passed
A21: 46078 | D21: Spanish | E21: Luis Ferrer | F21: 185242799 | G21: 3855838763 | H21: Night Shift | I21: Mechanical Assembly | J21: WJ | K21: NM | L21: Pending | M21: Passed | N21: Passed | O21: Yes
A22: 46076 | D22: Spanish | E22: Sandra Ruiz | F22: 182082642 | G22: 3855367759 | H22: Night Shift | I22: Mechanical Assembly | J22: WJ | K22: NM | L22: Pending | M22: Passed | N22: Passed | O22: Yes
A23: 46076 | D23: Spanish | E23: Adalmiro Martinez | F23: 201730403 | G23: 3854309136 | H23: Day Shift | I23: Mechanical Assembly | J23: WJ | K23: NM | L23: Pending | M23: Passed | N23: Passed | O23: Yes
D24: Spanish | E24: Eduard Gil | F24: 217569760 | G24: 8015740260 | H24: Night Shift | I24: Mechanical Assembly | J24: WJ | K24: NM | L24: Passed | M24: Passed | N24: Passed | O24: Yes
D25: Spanish | E25: Vanessa Palma | F25: 216548342 | G25: 3854728364 | H25: Day Shift | I25: Mechanical Assembly | J25: WJ | K25: NM | L25: Pending | M25: Passed | N25: Passed | O25: Yes
C26: Wait List | D26: Spanish | E26: Marian Mendez | F26: 180458712 | G26: 8014405907 | H26: Day Shift | I26: Mechanical Assembly | J26: WJ | K26: NM | L26: Passed | M26: Passed | N26: Passed
A27: 46066 | D27: Spanish | E27: Priscilla Castillo | F27: 218038437 | G27: 8016083151 | H27: Night Shift | I27: Mechanical Assembly | J27: WVC | K27: HB | L27: Passed | M27: Passed | N27: Passed
A28: 46065 | D28: Spanish | E28: Gabriela Martinez | F28: 218486983 | G28: 9564496694 | H28: Night Shift | I28: Mechanical Assembly | J28: WJ | K28: NM | L28: Pending | M28: Passed | N28: Passed | O28: Yes
A29: 46065 | D29: Spanish | E29: Jorcer Chirinos | F29: 218487075 | G29: 3473688551 | H29: Night Shift | I29: Mechanical Assembly | J29: WJ | K29: NM | L29: Pending | M29: Passed | N29: Passed | O29: Yes
A30: 46065 | D30: English | E30: Christopher Mok | F30: 133343283 | G30: 3855293558 | H30: Night Shift | I30: Mechanical Assembly | J30: WJ | K30: NM | L30: Passed | M30: Passed | N30: Passed | O30: Yes
A31: 46065 | D31: Bilingual | E31: Stephanie Pimentel | F31: 209054687 | G31: 714 657-0986 | H31: Day Shift | I31: Mechanical Assembly | J31: WJ | K31: NM | L31: Pending | M31: Passed | N31: Passed | O31: Yes
A32: 46065 | D32: Spanish | E32: Idel Silva | F32: 218432819 | G32: 8013014999 | H32: Night Shift | I32: Mechanical Assembly | J32: WJ | K32: NM | L32: Passed | M32: Passed | N32: Passed | O32: Yes
A33: 46064 | D33: Spanish | E33: Tony Jovo | F33: 218446551 | G33: 4072886356 | H33: Night Shift | I33: Mechanical Assembly | J33: WJ | K33: NM | L33: Passed | M33: Passed | N33: Passed | O33: Yes
A34: 46063 | D34: Spanish | E34: Luiseni Gonzalez | F34: 164355124 | G34: 3855021965 | H34: Day Shift | I34: Mechanical Assembly | J34: WJ | K34: NM | L34: Passed | M34: Passed | N34: Passed | O34: Yes
A35: 46059 | D35: English | E35: Maddox Trinh | F35: 203395747 | G35: 385 630-7207 | H35: Night Shift | I35: Mechanical Assembly | J35: NSL | K35: GKW | L35: Pending | M35: Passed | N35: Passed
A36: 46059 | D36: Spanish | E36: Maria Hernandez | F36: 177591908 | G36: 385 549 4599 | H36: Day Shift | I36: Mechanical Assembly | J36: WVC | K36: SM | L36: Passed | M36: Passed | N36: Passed | O36: Yes
A37: 46059 | D37: Spanish | E37: Sharis Luna | F37: 213034437 | G37: 8014031625 | H37: Day Shift | I37: Mechanical Assembly | J37: WVC | K37: SM | L37: Passed | M37: Passed | N37: Passed | O37: Yes
A38: 46059 | D38: Spanish | E38: Niurka Solares | F38: 218237562 | G38: 8013179423 | H38: Day Shift | I38: Mechanical Assembly | J38: WJ | K38: BL | L38: Passed | M38: Passed | N38: Passed
A39: 46058 | D39: Spanish | E39: María Ibarra | F39: 168121931 | G39: 8015849577 | H39: Day Shift | I39: Mechanical Assembly | J39: WJ | K39: BL | L39: Passed | M39: Passed | N39: Passed
A40: 46057 | D40: Spanish | E40: Jaidy Jimenez | F40: 218032291 | G40: 3855261356 | H40: Night Shift | I40: Mechanical Assembly | J40: WJ | K40: NM | L40: Passed | M40: Passed | N40: Passed | O40: Yes
...

Sheet Scorecard
A1: Tracks candidates from the Started column on start-date tabs only. Add a new row (copy the formulas across) when a new recruiter code is added. | H1: Tracks candidates from the Started column on start-date tabs only, grouped by Office (via PrepList, matched by Bold ID). Offices are fixed (WVC, WJ, NSL) - no rows to add unless a new office is created. | O1: Position List (dropdown source)
O2: Mechanical Assembly
A3: Recruiter | B3: Placed on Start Tabs | C3: Started | D3: No Show | E3: Still Pending | F3: Start Rate | H3: Office | I3: Placed on Start Tabs | J3: Started | K3: No Show | L3: Still Pending | M3: Start Rate | O3: Materials
A4: AR | B4: =COUNTIF(tbl_StartedStatus[Recruiter],A4) -> 0 | C4: =COUNTIFS(tbl_StartedStatus[Recruiter],A4,tbl_StartedStatus[Started],"Started") -> 0 | D4: =COUNTIFS(tbl_StartedStatus[Recruiter],A4,tbl_StartedStatus[Started],"No Show") -> 0 | E4: =B4-C4-D4 -> 0 | F4: =IF(C4+D4=0,"",C4/(C4+D4)) | H4: NSL | I4: =COUNTIF(_StartedStatus!$AA:$AA,H4) -> 5 | J4: =COUNTIFS(_StartedStatus!$AA:$AA,H4,_StartedStatus!$A:$A,"Started") -> 0 | K4: =COUNTIFS(_StartedStatus!$AA:$AA,H4,_StartedStatus!$A:$A,"No Show") -> 0 | L4: =I4-J4-K4 -> 5 | M4: =IF(J4+K4=0,"",J4/(J4+K4)) | O4: Rack Assembly
A5: BL | B5: =COUNTIF(tbl_StartedStatus[Recruiter],A5) -> 13 | C5: =COUNTIFS(tbl_StartedStatus[Recruiter],A5,tbl_StartedStatus[Started],"Started") -> 0 | D5: =COUNTIFS(tbl_StartedStatus[Recruiter],A5,tbl_StartedStatus[Started],"No Show") -> 0 | E5: =B5-C5-D5 -> 13 | F5: =IF(C5+D5=0,"",C5/(C5+D5)) | H5: WVC | I5: =COUNTIF(_StartedStatus!$AA:$AA,H5) -> 12 | J5: =COUNTIFS(_StartedStatus!$AA:$AA,H5,_StartedStatus!$A:$A,"Started") -> 0 | K5: =COUNTIFS(_StartedStatus!$AA:$AA,H5,_StartedStatus!$A:$A,"No Show") -> 0 | L5: =I5-J5-K5 -> 12 | M5: =IF(J5+K5=0,"",J5/(J5+K5)) | O5: IT Support
A6: CE | B6: =COUNTIF(tbl_StartedStatus[Recruiter],A6) -> 0 | C6: =COUNTIFS(tbl_StartedStatus[Recruiter],A6,tbl_StartedStatus[Started],"Started") -> 0 | D6: =COUNTIFS(tbl_StartedStatus[Recruiter],A6,tbl_StartedStatus[Started],"No Show") -> 0 | E6: =B6-C6-D6 -> 0 | F6: =IF(C6+D6=0,"",C6/(C6+D6)) | H6: WJ | I6: =COUNTIF(_StartedStatus!$AA:$AA,H6) -> 28 | J6: =COUNTIFS(_StartedStatus!$AA:$AA,H6,_StartedStatus!$A:$A,"Started") -> 0 | K6: =COUNTIFS(_StartedStatus!$AA:$AA,H6,_StartedStatus!$A:$A,"No Show") -> 0 | L6: =I6-J6-K6 -> 28 | M6: =IF(J6+K6=0,"",J6/(J6+K6)) | O6: Delivery Systems Analyst
A7: CN | B7: =COUNTIF(tbl_StartedStatus[Recruiter],A7) -> 0 | C7: =COUNTIFS(tbl_StartedStatus[Recruiter],A7,tbl_StartedStatus[Started],"Started") -> 0 | D7: =COUNTIFS(tbl_StartedStatus[Recruiter],A7,tbl_StartedStatus[Started],"No Show") -> 0 | E7: =B7-C7-D7 -> 0 | F7: =IF(C7+D7=0,"",C7/(C7+D7)) | H7: TOTAL | I7: =SUM(I4:I6) -> 45 | J7: =SUM(J4:J6) -> 0 | K7: =SUM(K4:K6) -> 0 | L7: =SUM(L4:L6) -> 45 | M7: =IF(J7+K7=0,"",J7/(J7+K7)) | O7: Quality
A8: DG | B8: =COUNTIF(tbl_StartedStatus[Recruiter],A8) -> 0 | C8: =COUNTIFS(tbl_StartedStatus[Recruiter],A8,tbl_StartedStatus[Started],"Started") -> 0 | D8: =COUNTIFS(tbl_StartedStatus[Recruiter],A8,tbl_StartedStatus[Started],"No Show") -> 0 | E8: =B8-C8-D8 -> 0 | F8: =IF(C8+D8=0,"",C8/(C8+D8)) | O8: Test Operator
A9: DR | B9: =COUNTIF(tbl_StartedStatus[Recruiter],A9) -> 6 | C9: =COUNTIFS(tbl_StartedStatus[Recruiter],A9,tbl_StartedStatus[Started],"Started") -> 0 | D9: =COUNTIFS(tbl_StartedStatus[Recruiter],A9,tbl_StartedStatus[Started],"No Show") -> 0 | E9: =B9-C9-D9 -> 6 | F9: =IF(C9+D9=0,"",C9/(C9+D9)) | O9: Debug
A10: EP | B10: =COUNTIF(tbl_StartedStatus[Recruiter],A10) -> 3 | C10: =COUNTIFS(tbl_StartedStatus[Recruiter],A10,tbl_StartedStatus[Started],"Started") -> 0 | D10: =COUNTIFS(tbl_StartedStatus[Recruiter],A10,tbl_StartedStatus[Started],"No Show") -> 0 | E10: =B10-C10-D10 -> 3 | F10: =IF(C10+D10=0,"",C10/(C10+D10))
A11: FZ | B11: =COUNTIF(tbl_StartedStatus[Recruiter],A11) -> 7 | C11: =COUNTIFS(tbl_StartedStatus[Recruiter],A11,tbl_StartedStatus[Started],"Started") -> 0 | D11: =COUNTIFS(tbl_StartedStatus[Recruiter],A11,tbl_StartedStatus[Started],"No Show") -> 0 | E11: =B11-C11-D11 -> 7 | F11: =IF(C11+D11=0,"",C11/(C11+D11)) | O11: Last Refreshed: | P11: =IFERROR(_StartedStatus!$Z$2,"") -> 46275.48
A12: GKW | B12: =COUNTIF(tbl_StartedStatus[Recruiter],A12) -> 5 | C12: =COUNTIFS(tbl_StartedStatus[Recruiter],A12,tbl_StartedStatus[Started],"Started") -> 0 | D12: =COUNTIFS(tbl_StartedStatus[Recruiter],A12,tbl_StartedStatus[Started],"No Show") -> 0 | E12: =B12-C12-D12 -> 5 | F12: =IF(C12+D12=0,"",C12/(C12+D12))
A13: JM | B13: =COUNTIF(tbl_StartedStatus[Recruiter],A13) -> 8 | C13: =COUNTIFS(tbl_StartedStatus[Recruiter],A13,tbl_StartedStatus[Started],"Started") -> 0 | D13: =COUNTIFS(tbl_StartedStatus[Recruiter],A13,tbl_StartedStatus[Started],"No Show") -> 0 | E13: =B13-C13-D13 -> 8 | F13: =IF(C13+D13=0,"",C13/(C13+D13))
A14: JY | B14: =COUNTIF(tbl_StartedStatus[Recruiter],A14) -> 9 | C14: =COUNTIFS(tbl_StartedStatus[Recruiter],A14,tbl_StartedStatus[Started],"Started") -> 0 | D14: =COUNTIFS(tbl_StartedStatus[Recruiter],A14,tbl_StartedStatus[Started],"No Show") -> 0 | E14: =B14-C14-D14 -> 9 | F14: =IF(C14+D14=0,"",C14/(C14+D14))
A15: NM | B15: =COUNTIF(tbl_StartedStatus[Recruiter],A15) -> 26 | C15: =COUNTIFS(tbl_StartedStatus[Recruiter],A15,tbl_StartedStatus[Started],"Started") -> 0 | D15: =COUNTIFS(tbl_StartedStatus[Recruiter],A15,tbl_StartedStatus[Started],"No Show") -> 0 | E15: =B15-C15-D15 -> 26 | F15: =IF(C15+D15=0,"",C15/(C15+D15))
A16: RP | B16: =COUNTIF(tbl_StartedStatus[Recruiter],A16) -> 15 | C16: =COUNTIFS(tbl_StartedStatus[Recruiter],A16,tbl_StartedStatus[Started],"Started") -> 0 | D16: =COUNTIFS(tbl_StartedStatus[Recruiter],A16,tbl_StartedStatus[Started],"No Show") -> 0 | E16: =B16-C16-D16 -> 15 | F16: =IF(C16+D16=0,"",C16/(C16+D16))
A17: SM | B17: =COUNTIF(tbl_StartedStatus[Recruiter],A17) -> 0 | C17: =COUNTIFS(tbl_StartedStatus[Recruiter],A17,tbl_StartedStatus[Started],"Started") -> 0 | D17: =COUNTIFS(tbl_StartedStatus[Recruiter],A17,tbl_StartedStatus[Started],"No Show") -> 0 | E17: =B17-C17-D17 -> 0 | F17: =IF(C17+D17=0,"",C17/(C17+D17))
A18: TOTAL | B18: =SUM(B4:B17) -> 92 | C18: =SUM(C4:C17) -> 0 | D18: =SUM(D4:D17) -> 0 | E18: =SUM(E4:E17) -> 92 | F18: =IF(C18+D18=0,"",C18/(C18+D18))

Sheet Variables
A1: Department: | B1: Interested | C1: Cleared
A2: Production Specialist 1 - Mechanical Assembly - A&C Shift
A3: Production Specialist 1 - Mechanical Assembly - B&D shift
A21: Total

Sheet Dashboard For Flex
A1: Applications | C1: Phone Screens | E1: Interviews | G1: Resume Subs
A2: Goal | B2: Attn | C2: Goal | D2: Attn | E2: Interviews Scheduled for today | F2: Interviews Scheduled for tomorrow | G2: Goal | H2: Attn | I2: Offers accepted | J2: Total in Pipeline | K2: Production Specialist 1 - Mechanical Assembly - A&C Shift | L2: Production Specialist 1 - Mechanical Assembly - A&C Shift Background cleared | M2: Production Specialist 1 - Mechanical Assembly - B&D shift | N2: Production Specialist 1 - Mechanical Assembly - B&D shift Background cleared | O2: Production Specialist 1 - Materials - A&C shift | P2: Production Specialist 1 - Materials - A&C shift Background cleared | Q2: Production Specialist 1 - Materials - B&D shift | R2: Production Specialist 1 - Materials - B&D shiftBackground cleared | S2: Production Specialist 1 - Rack Level Assembly - A&C shift | T2: Production Specialist 1 - Rack Level Assembly - A&C shift Background cleared | U2: Production Specialist 1 - Rack Level Assembly - B&D shift | V2: Production Specialist 1 - Rack Level Assembly - B&D shift Background cleared | W2: IT Support Technician - 1st Shift | X2: IT Support Technician - 1st Shift - Background cleared | Y2: Delivery Business Systems Analyst - 1st Shift | Z2: Delivery Business Systems Analyst - 1st Shift - Background cleared | AA2: Production Specialist 1 -Quality - B&D shift | AB2: Production Specialist 1 - Quality - B&D shift - Background cleared | AC2: Production Specialist 1 -Test Opertor - A&Cshift | AD2: Production Specialist 1 - Test Opertor - A&C shift - Background cleared | AE2: Production Specialist 1 - Mechanical Assy Debug - A&C shift | AF2: Production Specialist 1 - Mechanical Assy Debug - A&C shift - Background cleared | AG2: Debug Tech 4 - B&D shift | AH2: Debug Tech 4 - B&D shift - Background cleared | AI2: HR Generalist - 1st Shift | AJ2: Recruiter 1st Shift | AK2: Production Specialist 1 -Test Opertor - 1st shift | AL2: Production Specialist 1 - Test Opertor - 1st shift - Background cleared | AM2: Production Specialist 1 - Mechanical Assy Debug - 1st shift | AN2: Production Specialist 1 - Mechanical Assy Debug - 1st shift - Background cleared | AO2: Debug Tech 4 - 2nd shift | AP2: Debug Tech 4 - 2nd shift - Background cleared | AQ2: HR Generalist - 1st Shift | AR2: Recruiter 1st Shift

Sheet Dashboard
A1: Department: | B1: Interested | C1: Cleared
A2: Production Specialist 1 - Mechanical Assembly - 1st shift | B2: =COUNTIFS(PrepList!E:E,Dashboard!A2,PrepList'!M:M,"No") | C2: =COUNTIFS('1.PrepList'!#REF!,Dashboard!A2,'1.PrepList'!#REF!,"Yes") -> #REF!
A3: Production Specialist 1 - Mechanical Assembly - 2nd shift | B3: =COUNTIFS('1.PrepList'!J:J,Dashboard!A3,'1.PrepList'!#REF!,"No") -> #REF! | C3: =COUNTIFS('1.PrepList'!#REF!,Dashboard!A3,'1.PrepList'!#REF!,"Yes") -> #REF!
A4: Production Specialist 1 - Materials - 1st shift | B4: =COUNTIFS('1.PrepList'!J:J,Dashboard!A4,'1.PrepList'!#REF!,"No") -> #REF! | C4: =COUNTIFS('1.PrepList'!#REF!,Dashboard!A4,'1.PrepList'!#REF!,"Yes") -> #REF!
A5: Production Specialist 1 - Materials - 2nd shift | B5: =COUNTIFS('1.PrepList'!J:J,Dashboard!A5,'1.PrepList'!#REF!,"No") -> #REF! | C5: =COUNTIFS('1.PrepList'!#REF!,Dashboard!A5,'1.PrepList'!#REF!,"Yes") -> #REF!
A6: Production Specialist 1 - Materials - 3rd shift | B6: =COUNTIFS('1.PrepList'!J:J,Dashboard!A6,'1.PrepList'!#REF!,"No") -> #REF! | C6: =COUNTIFS('1.PrepList'!#REF!,Dashboard!A6,'1.PrepList'!#REF!,"Yes") -> #REF!
A7: Production Specialist 1 - Mechanical Assembly - 3rd shift | B7: =COUNTIFS('1.PrepList'!J:J,Dashboard!A7,'1.PrepList'!#REF!,"No") -> #REF! | C7: =COUNTIFS('1.PrepList'!#REF!,Dashboard!A7,'1.PrepList'!#REF!,"Yes") -> #REF!
A8: Production Specialist 1 - Rack Level Assembly - 3rd shift | B8: =COUNTIFS('1.PrepList'!J:J,Dashboard!A8,'1.PrepList'!#REF!,"No") -> #REF! | C8: =COUNTIFS('1.PrepList'!#REF!,Dashboard!A8,'1.PrepList'!#REF!,"Yes") -> #REF!
A9: Production Specialist 1 - Packout - 3rd shift | B9: =COUNTIFS('1.PrepList'!J:J,Dashboard!A9,'1.PrepList'!#REF!,"No") -> #REF! | C9: =COUNTIFS('1.PrepList'!#REF!,Dashboard!A9,'1.PrepList'!#REF!,"Yes") -> #REF!
A10: Production Specialist 1 - Rack Level Assembly - 3rd shift | B10: =COUNTIFS('1.PrepList'!J:J,Dashboard!A10,'1.PrepList'!#REF!,"No") -> #REF! | C10: =COUNTIFS('1.PrepList'!#REF!,Dashboard!A10,'1.PrepList'!#REF!,"Yes") -> #REF!
A11: Production Specialist 1 - Rack Level Assembly -1st shift | B11: =COUNTIFS('1.PrepList'!J:J,Dashboard!A11,'1.PrepList'!#REF!,"No") -> #REF! | C11: =COUNTIFS('1.PrepList'!#REF!,Dashboard!A11,'1.PrepList'!#REF!,"Yes") -> #REF!
A12: Production Specialist 1 - Rack Level Assembly -2nd shift | B12: =COUNTIFS('1.PrepList'!J:J,Dashboard!A12,'1.PrepList'!#REF!,"No") -> #REF! | C12: =COUNTIFS('1.PrepList'!#REF!,Dashboard!A12,'1.PrepList'!#REF!,"Yes") -> #REF!
A13: IT Support Technician - 1st Shift | B13: =COUNTIFS('1.PrepList'!J:J,Dashboard!A13,'1.PrepList'!#REF!,"No") -> #REF! | C13: =COUNTIFS('1.PrepList'!#REF!,Dashboard!A13,'1.PrepList'!#REF!,"Yes") -> #REF!
A14: Delivery Business Systems Analyst - 1st Shift | B14: =COUNTIFS('1.PrepList'!J:J,Dashboard!A14,'1.PrepList'!#REF!,"No") -> #REF! | C14: =COUNTIFS('1.PrepList'!#REF!,Dashboard!A14,'1.PrepList'!#REF!,"Yes") -> #REF!
... A20: Recruiter 1st Shift | B20: =COUNTIFS('1.PrepList'!J:J,Dashboard!A20,'1.PrepList'!#REF!,"No") -> #REF! | C20: =COUNTIFS('1.PrepList'!#REF!,Dashboard!A20,'1.PrepList'!#REF!,"Yes") -> #REF!
A21: Total | B21: =SUM(B2:B20) -> #REF! | C21: =SUM(C2:C20) -> #REF!

Sheet Office Goals
A1: 2.24 - 2.28 | D1: as of 2.26
A2: Office | B2: Goal | C2: Actual
A3: NSL | B3: 10 | C3: 16
A4: WVC | B4: 20 | C4: 45
A5: WJ | B5: 20 | C5: 23
A6: Total | B6: =SUM(B3:B5) -> 50 | C6: =SUM(C3:C5) -> 84
A8: 3.03 - 3.07
A9: Office | B9: Goal | C9: Actual
A10: NSL | B10: 10
A11: WVC | B11: 20
A12: WJ | B12: 20
A13: Total | B13: =SUM(B10:B12) -> 50 | C13: =SUM(C10:C12) -> 0

Sheet MGR&Shifts
A1: Work Location | B1: Shift_Time | C1: Manager
A2: SLC-WH-RECIEVING & SHIPPING | B2: 0700a-0400p M-F some Saturday's | C2: Adam Coghlan (1034757)
A3: SLC-RACK ASSY- SUPERVISOR ASSY | B3: 8:30am to 5:00pm | C3: Alex Martinez
A4: SLC-RACK ASSY-IQA INSPECTION | B4: Salt Lake City- C 1st Shift 0630a-0300p Mon-Fri | C4: Alondra Landin (1152847)
A5: SLC-MECH ASSY- SUPERVISOR ASSY | B5: Salt Lake City - 12 - 0300p-1130p M-F | C5: Avigail Zamora
A6: SLC-MECH ASSY-ASSEMBLY | B6: 0800a-0500p M 1000a-0700p T-F | C6: Barbara Garcia (1137177)
A7: SLC-MECH ASSY-REWORK | B7: Salt Lake City- F 2nd Shift 0200p-1230a Mon-Th (15% Diff) | C7: Britton Hanna (1154396)
A8: SLC-RACK ASSY- SHIPPING | B8: Salt Lake City- Wknd Shift 0230p-0230a F-Sun (15% Diff) | C8: Castalia Marino
A9: SLC-WH-LEAD | B9: 0230p-1100p M-F some Saturday's | C9: Cristian Vega (1135987)
A10: SLC-MECH ASSY- WATER SPIDER | B10: Salt Lake City- D 1st Shift 0700a-0330p Mon-Fri | C10: Dallas Driggers (1156397)
A11: SLC-MECH ASSY-KITTING | B11: 0400p-0100a M-F some Saturday's | C11: Danilo Vieira De Souza Alves (60729)
A12: SLC-MECH ASSY-DETRASH | B12: 0330p-1200a M-F some Saturday's | C12: David Hiestand (1138434)
... A41: SLC-RACK ASSY-WATERSPIDER | B41: Salt Lake City - L - 10:00 PM - 6:30 AM (Sun-Thurs) | C41: Zee Fruechting (1167899)

Sheet Completed Orientation
A1: Employee Name | B1: Phone # | C1: Preferred Schedule | D1: Shift Requirement | E1: Position
A2: Ivonne Galban | B2: 801-500-3133 | C2: A/C (Day) | E2: =ROW() - ROW(Table52[[#Headers],[Position]]) -> 1
A3: Yulimar M Nazarin | B3: 313-523-3391 | C3: A/C (Day) | E3: =ROW() - ROW(Table52[[#Headers],[Position]]) -> 2
A4: Sindy Viviana Guillen Taborda | B4: 385-343-2625 | C4: A/C (Day) | E4: =ROW() - ROW(Table52[[#Headers],[Position]]) -> 3
A5: Abel Elias Huaman Huachopoma | B5: 385-421-1590 | C5: A/C (Day) | E5: =ROW() - ROW(Table52[[#Headers],[Position]]) -> 4
A6: David C Huaman Julian | B6: 801-946-9851 | C6: A/C (Day) | E6: =ROW() - ROW(Table52[[#Headers],[Position]]) -> 5
A7: Stivaliz Chirino | B7: 385-267-0910 | C7: A/C (Day) | E7: =ROW() - ROW(Table52[[#Headers],[Position]]) -> 6
A8: Cruzmar Danielo Azuaje Briceno | B8: 801-895-1504 | C8: A/C (Day) | E8: =ROW() - ROW(Table52[[#Headers],[Position]]) -> 7
A9: Gloria N Navarro | B9: 385-302-2818 | C9: A/C (Day) | E9: =ROW() - ROW(Table52[[#Headers],[Position]]) -> 8
A10: Maria Duram | B10: 689-204-4662 | C10: A/C (Day) | E10: =ROW() - ROW(Table52[[#Headers],[Position]]) -> 9
A11: Ginelda Palmar | B11: 385-343-9591 | C11: A/C (Day) | E11: =ROW() - ROW(Table52[[#Headers],[Position]]) -> 10
A12: Juan Acero Diaz | B12: 813-521-3185 | C12: A/C (Day) | E12: =ROW() - ROW(Table52[[#Headers],[Position]]) -> 11
A13: Maria Mercedes Ibarra | B13: 801-584-9577 | C13: A/C (Day) | E13: =ROW() - ROW(Table52[[#Headers],[Position]]) -> 12
... A15: Juan Nova | B15: 385-576-3439 | C15: A/C (Day) | E15: =ROW() - ROW(Table52[[#Headers],[Position]]) -> 14
A16: Jesse Gonzalez | C16: A/C (Day) | E16: =ROW() - ROW(Table52[[#Headers],[Position]]) -> 15
A17: Christian Crush | C17: A/C (Day) | E17: =ROW() - ROW(Table52[[#Headers],[Position]]) -> 16
A18: Gabriela Molina | B18: 385-267-9020 | C18: A/C (Day) | D18: Luzmila Ballesteros | E18: =ROW() - ROW(Table52[[#Headers],[Position]]) -> 17
A19: Jesse Gonzalez | B19: 801-809-7918 | C19: A/C (Day) | E19: =ROW() - ROW(Table52[[#Headers],[Position]]) -> 18
A20: Christian Crush | B20: 409-730-6234 | C20: A/C (Day) | E20: =ROW() - ROW(Table52[[#Headers],[Position]]) -> 19
A21: Gisell Carmona | B21: 385-441-2390 | C21: A/C (Day) | D21: Catherine Rodriguez | E21: =ROW() - ROW(Table52[[#Headers],[Position]]) -> 20
A22: Catherine Rodriguez | B22: (801) 330-2018 | C22: A/C (Day) | D22: Gisell Carmona | E22: =ROW() - ROW(Table52[[#Headers],[Position]]) -> 21
A23: Mariely Gonzalez | B23: 801-674-5096 | C23: A/C (Day) | E23: =ROW() - ROW(Table52[[#Headers],[Position]]) -> 22
A24: Craig Allen Foster | B24: 406-381-3640 | C24: A/C (Day) | E24: =ROW() - ROW(Table52[[#Headers],[Position]]) -> 23
A25: Lizbeth Zavala | B25: 801-708-9014 | C25: A/C (Day) | E25: =ROW() - ROW(Table52[[#Headers],[Position]]) -> 24
A26: Syreefa Yazzie | B26: 385-887-1774 | C26: A/C (Day) | D26: Timothy Alires | E26: =ROW() - ROW(Table52[[#Headers],[Position]]) -> 25
A27: Jerja Chatterton | B27: 435-755-0810 | C27: A/C (Day) | E27: =ROW() - ROW(Table52[[#Headers],[Position]]) -> 26
A28: Jennifer Lee | B28: 385-258-9659 | C28: A/C (Day) | E28: =ROW() - ROW(Table52[[#Headers],[Position]]) -> 27
A29: Sabha Abrena | B29: 385-299-1604 | C29: A/C (Day) | E29: =ROW() - ROW(Table52[[#Headers],[Position]]) -> 28
A30: Taylor W Lawer | B30: 707-378-3290 | C30: A/C (Day) | E30: =ROW() - ROW(Table52[[#Headers],[Position]]) -> 29
A31: Sophie Wesseh | B31: 385-520-3599 | C31: A/C (Day) | E31: =ROW() - ROW(Table52[[#Headers],[Position]]) -> 30
A32: Norris John | B32: 949-393-8177 | C32: A/C (Day) | D32: 385-401-3966 | E32: =ROW() - ROW(Table52[[#Headers],[Position]]) -> 31
A33: Lotomaci BJ Uluset? | B33: 385-566-7922 | C33: A/C (Day) | D33: Robert Tiana | E33: =ROW() - ROW(Table52[[#Headers],[Position]]) -> 32
A34: Rober Tiana | B34: 385-566-7922 | C34: A/C (Day) | D34: BJ | E34: =ROW() - ROW(Table52[[#Headers],[Position]]) -> 33
A35: Arely Cardenas | B35: 801-824-7474 | C35: A/C (Day) | D35: C | E35: =ROW() - ROW(Table52[[#Headers],[Position]]) -> 34
A36: Ulises Anzaldo | B36: 385-770-9129 | C36: A/C (Day) | E36: =ROW() - ROW(Table52[[#Headers],[Position]]) -> 35
A37: Hawa Enow | B37: 801-618-5641 | C37: A/C (Day) | E37: =ROW() - ROW(Table52[[#Headers],[Position]]) -> 36
A38: Jhony Mauricio | B38: 385-900-6827 | C38: A/C (Day) | E38: =ROW() - ROW(Table52[[#Headers],[Position]]) -> 37
A39: Mary Cruz Parra | B39: 385-461-2852 | C39: A/C (Day) | E39: =ROW() - ROW(Table52[[#Headers],[Position]]) -> 38
A40: Yendri Merentes | B40: 801-430-4477 | C40: A/C (Day) | E40: =ROW() - ROW(Table52[[#Headers],[Position]]) -> 39
A41: Angel Enrique Chacin Romero | B41: 801-414-0925 | C41: A/C (Day) | E41: =ROW() - ROW(Table52[[#Headers],[Position]]) -> 40
...

Sheet Ready to Start
A1: Mini Completed Date | B1: Language | C1: Employee Name | D1: Bold ID | E1: Phone | F1: Shift | G1: Position | H1: A.M. | I1: BG | J1: DT | K1: EV | L1: FLEX Doc Sent | M1: Ready to Start | N1: Notes
B2: =IF('1.PrepList'!#REF!="","",'1.PrepList'!#REF!) -> #REF! | C2: =_xlfn.XLOOKUP(D2,'1.PrepList'!H:H,'1.PrepList'!G:G) -> #REF! | D2: =IF('1.PrepList'!#REF!="","",'1.PrepList'!#REF!) -> #REF! | E2: =IF('1.PrepList'!#REF!="","",'1.PrepList'!#REF!) -> #REF! | F2: =IF('1.PrepList'!#REF!="","",'1.PrepList'!#REF!) -> #REF! | G2: =IF('1.PrepList'!#REF!="","",'1.PrepList'!#REF!) -> #REF! | H2: =IF('1.PrepList'!#REF!="","",'1.PrepList'!#REF!) -> #REF! | I2: =IF('1.PrepList'!#REF!="","",'1.PrepList'!#REF!) -> #REF! | J2: =IF('1.PrepList'!#REF!="","",'1.PrepList'!#REF!) -> #REF! | L2: =IF('1.PrepList'!#REF!="","",'1.PrepList'!#REF!) -> #REF! | N2: =IF('1.PrepList'!#REF!="","",'1.PrepList'!#REF!) -> #REF!
B3: =IF('1.PrepList'!#REF!="","",'1.PrepList'!#REF!) -> #REF! | C3: =_xlfn.XLOOKUP(D3,'1.PrepList'!H:H,'1.PrepList'!G:G) -> #REF! | D3: =IF('1.PrepList'!#REF!="","",'1.PrepList'!#REF!) -> #REF! | E3: =IF('1.PrepList'!#REF!="","",'1.PrepList'!#REF!) -> #REF! | F3: =IF('1.PrepList'!#REF!="","",'1.PrepList'!#REF!) -> #REF! | G3: =IF('1.PrepList'!#REF!="","",'1.PrepList'!#REF!) -> #REF! | H3: =IF('1.PrepList'!#REF!="","",'1.PrepList'!#REF!) -> #REF! | I3: =IF('1.PrepList'!#REF!="","",'1.PrepList'!#REF!) -> #REF! | J3: =IF('1.PrepList'!#REF!="","",'1.PrepList'!#REF!) -> #REF! | L3: =IF('1.PrepList'!#REF!="","",'1.PrepList'!#REF!) -> #REF! | N3: =IF('1.PrepList'!#REF!="","",'1.PrepList'!#REF!) -> #REF!
B4: =IF('1.PrepList'!#REF!="","",'1.PrepList'!#REF!) -> #REF! | C4: =_xlfn.XLOOKUP(D4,'1.PrepList'!H:H,'1.PrepList'!G:G) -> #REF! | D4: =IF('1.PrepList'!#REF!="","",'1.PrepList'!#REF!) -> #REF! | E4: =IF('1.PrepList'!#REF!="","",'1.PrepList'!#REF!) -> #REF! | F4: =IF('1.PrepList'!#REF!="","",'1.PrepList'!#REF!) -> #REF! | G4: =IF('1.PrepList'!#REF!="","",'1.PrepList'!#REF!) -> #REF! | H4: =IF('1.PrepList'!#REF!="","",'1.PrepList'!#REF!) -> #REF! | I4: =IF('1.PrepList'!#REF!="","",'1.PrepList'!#REF!) -> #REF! | J4: =IF('1.PrepList'!#REF!="","",'1.PrepList'!#REF!) -> #REF! | L4: =IF('1.PrepList'!#REF!="","",'1.PrepList'!#REF!) -> #REF! | N4: =IF('1.PrepList'!#REF!="","",'1.PrepList'!#REF!) -> #REF!
